{"meta":{"name":"Unnamed","author":"xMsBean","description":"","size":{"width":32,"height":25,"length":31},"blockCount":3654,"expectedTotalBlocks":3654,"entityCount":13,"tileEntityCount":158},"placements":[{"x":6,"y":0,"z":5,"name":"dark_oak_wall_sign","properties":{"waterlogged":"false","facing":"north"},"nbt":{"back_text":{"has_glowing_text":0,"color":"black","messages":["\"\"","\"\"","\"\"","\"\""]},"is_waxed":0,"x":6,"y":0,"z":5,"id":"minecraft:sign","front_text":{"has_glowing_text":0,"color":"black","messages":["\"\"","\"\"","\"\"","\"\""]}}},{"x":14,"y":0,"z":5,"name":"dark_oak_wall_sign","properties":{"waterlogged":"false","facing":"north"},"nbt":{"back_text":{"has_glowing_text":0,"color":"black","messages":["\"\"","\"\"","\"\"","\"\""]},"is_waxed":0,"x":14,"y":0,"z":5,"id":"minecraft:sign","front_text":{"has_glowing_text":0,"color":"black","messages":["\"\"","\"\"","\"\"","\"\""]}}},{"x":5,"y":0,"z":6,"name":"dark_oak_wall_sign","properties":{"waterlogged":"false","facing":"west"},"nbt":{"back_text":{"has_glowing_text":0,"color":"black","messages":["\"\"","\"\"","\"\"","\"\""]},"is_waxed":0,"x":5,"y":0,"z":6,"id":"minecraft:sign","front_text":{"has_glowing_text":0,"color":"black","messages":["\"\"","\"\"","\"\"","\"\""]}}},{"x":6,"y":0,"z":6,"name":"stripped_spruce_wood","properties":{"axis":"y"}},{"x":7,"y":0,"z":6,"name":"oak_leaves","properties":{"waterlogged":"false","distance":"1","persistent":"true"}},{"x":8,"y":0,"z":6,"name":"oak_leaves","properties":{"waterlogged":"false","distance":"2","persistent":"true"}},{"x":9,"y":0,"z":6,"name":"oak_leaves","properties":{"waterlogged":"false","distance":"3","persistent":"true"}},{"x":10,"y":0,"z":6,"name":"oak_leaves","properties":{"waterlogged":"false","distance":"4","persistent":"true"}},{"x":11,"y":0,"z":6,"name":"oak_leaves","properties":{"waterlogged":"false","distance":"3","persistent":"true"}},{"x":12,"y":0,"z":6,"name":"oak_leaves","properties":{"waterlogged":"false","distance":"2","persistent":"true"}},{"x":13,"y":0,"z":6,"name":"oak_leaves","properties":{"waterlogged":"false","distance":"1","persistent":"true"}},{"x":14,"y":0,"z":6,"name":"stripped_spruce_wood","properties":{"axis":"y"}},{"x":15,"y":0,"z":6,"name":"dark_oak_wall_sign","properties":{"waterlogged":"false","facing":"east"},"nbt":{"back_text":{"has_glowing_text":0,"color":"black","messages":["\"\"","\"\"","\"\"","\"\""]},"is_waxed":0,"x":15,"y":0,"z":6,"id":"minecraft:sign","front_text":{"has_glowing_text":0,"color":"black","messages":["\"\"","\"\"","\"\"","\"\""]}}},{"x":6,"y":0,"z":7,"name":"oak_leaves","properties":{"waterlogged":"false","distance":"1","persistent":"true"}},{"x":7,"y":0,"z":7,"name":"cracked_stone_bricks","properties":{}},{"x":8,"y":0,"z":7,"name":"cracked_stone_bricks","properties":{}},{"x":9,"y":0,"z":7,"name":"cracked_stone_bricks","properties":{}},{"x":10,"y":0,"z":7,"name":"cobblestone","properties":{}},{"x":11,"y":0,"z":7,"name":"cracked_stone_bricks","properties":{}},{"x":12,"y":0,"z":7,"name":"stone","properties":{}},{"x":13,"y":0,"z":7,"name":"cobblestone","properties":{}},{"x":14,"y":0,"z":7,"name":"oak_leaves","properties":{"waterlogged":"false","distance":"1","persistent":"true"}},{"x":6,"y":0,"z":8,"name":"oak_leaves","properties":{"waterlogged":"false","distance":"1","persistent":"true"}},{"x":7,"y":0,"z":8,"name":"stone_bricks","properties":{}},{"x":8,"y":0,"z":8,"name":"spruce_trapdoor","properties":{"half":"bottom","waterlogged":"false","powered":"false","facing":"west","open":"true"}},{"x":9,"y":0,"z":8,"name":"spruce_trapdoor","properties":{"half":"top","waterlogged":"false","powered":"false","facing":"south","open":"false"}},{"x":10,"y":0,"z":8,"name":"spruce_trapdoor","properties":{"half":"top","waterlogged":"false","powered":"false","facing":"south","open":"false"}},{"x":11,"y":0,"z":8,"name":"spruce_trapdoor","properties":{"half":"top","waterlogged":"false","powered":"false","facing":"south","open":"false"}},{"x":12,"y":0,"z":8,"name":"spruce_trapdoor","properties":{"half":"bottom","waterlogged":"false","powered":"false","facing":"east","open":"true"}},{"x":13,"y":0,"z":8,"name":"cracked_stone_bricks","properties":{}},{"x":14,"y":0,"z":8,"name":"oak_leaves","properties":{"waterlogged":"false","distance":"1","persistent":"true"}},{"x":24,"y":0,"z":8,"name":"dark_oak_wall_sign","properties":{"waterlogged":"false","facing":"north"},"nbt":{"back_text":{"has_glowing_text":0,"color":"black","messages":["\"\"","\"\"","\"\"","\"\""]},"is_waxed":0,"x":24,"y":0,"z":8,"id":"minecraft:sign","front_text":{"has_glowing_text":0,"color":"black","messages":["\"\"","\"\"","\"\"","\"\""]}}},{"x":27,"y":0,"z":8,"name":"dark_oak_wall_sign","properties":{"waterlogged":"false","facing":"north"},"nbt":{"back_text":{"has_glowing_text":0,"color":"black","messages":["\"\"","\"\"","\"\"","\"\""]},"is_waxed":0,"x":27,"y":0,"z":8,"id":"minecraft:sign","front_text":{"has_glowing_text":0,"color":"black","messages":["\"\"","\"\"","\"\"","\"\""]}}},{"x":5,"y":0,"z":9,"name":"dark_oak_wall_sign","properties":{"waterlogged":"false","facing":"west"},"nbt":{"back_text":{"has_glowing_text":0,"color":"black","messages":["\"\"","\"\"","\"\"","\"\""]},"is_waxed":0,"x":5,"y":0,"z":9,"id":"minecraft:sign","front_text":{"has_glowing_text":0,"color":"black","messages":["\"\"","\"\"","\"\"","\"\""]}}},{"x":6,"y":0,"z":9,"name":"stripped_spruce_wood","properties":{"axis":"y"}},{"x":7,"y":0,"z":9,"name":"cobblestone","properties":{}},{"x":13,"y":0,"z":9,"name":"stone","properties":{}},{"x":14,"y":0,"z":9,"name":"stripped_spruce_wood","properties":{"axis":"y"}},{"x":15,"y":0,"z":9,"name":"oak_leaves","properties":{"waterlogged":"false","distance":"1","persistent":"true"}},{"x":16,"y":0,"z":9,"name":"oak_leaves","properties":{"waterlogged":"false","distance":"2","persistent":"true"}},{"x":17,"y":0,"z":9,"name":"oak_leaves","properties":{"waterlogged":"false","distance":"3","persistent":"true"}},{"x":18,"y":0,"z":9,"name":"oak_leaves","properties":{"waterlogged":"false","distance":"4","persistent":"true"}},{"x":19,"y":0,"z":9,"name":"oak_leaves","properties":{"waterlogged":"false","distance":"5","persistent":"true"}},{"x":20,"y":0,"z":9,"name":"oak_leaves","properties":{"waterlogged":"false","distance":"4","persistent":"true"}},{"x":21,"y":0,"z":9,"name":"oak_leaves","properties":{"waterlogged":"false","distance":"3","persistent":"true"}},{"x":22,"y":0,"z":9,"name":"oak_leaves","properties":{"waterlogged":"false","distance":"2","persistent":"true"}},{"x":23,"y":0,"z":9,"name":"oak_leaves","properties":{"waterlogged":"false","distance":"1","persistent":"true"}},{"x":24,"y":0,"z":9,"name":"stripped_spruce_wood","properties":{"axis":"y"}},{"x":25,"y":0,"z":9,"name":"dark_oak_fence","properties":{"east":"true","waterlogged":"false","south":"false","north":"false","west":"true"}},{"x":26,"y":0,"z":9,"name":"dark_oak_fence","properties":{"east":"true","waterlogged":"false","south":"false","north":"false","west":"true"}},{"x":27,"y":0,"z":9,"name":"stripped_spruce_log","properties":{"axis":"y"}},{"x":28,"y":0,"z":9,"name":"dark_oak_wall_sign","properties":{"waterlogged":"false","facing":"east"},"nbt":{"back_text":{"has_glowing_text":0,"color":"black","messages":["\"\"","\"\"","\"\"","\"\""]},"is_waxed":0,"x":28,"y":0,"z":9,"id":"minecraft:sign","front_text":{"has_glowing_text":0,"color":"black","messages":["\"\"","\"\"","\"\"","\"\""]}}},{"x":6,"y":0,"z":10,"name":"oak_leaves","properties":{"waterlogged":"false","distance":"1","persistent":"true"}},{"x":7,"y":0,"z":10,"name":"stone","properties":{}},{"x":8,"y":0,"z":10,"name":"furnace","properties":{"lit":"false","facing":"east"},"nbt":{"CookTime":0,"BurnTime":0,"x":8,"y":0,"Items":[],"z":10,"id":"minecraft:furnace","CookTimeTotal":0,"RecipesUsed":{}}},{"x":13,"y":0,"z":10,"name":"stone","properties":{}},{"x":14,"y":0,"z":10,"name":"cobblestone","properties":{}},{"x":15,"y":0,"z":10,"name":"cracked_stone_bricks","properties":{}},{"x":16,"y":0,"z":10,"name":"stone","properties":{}},{"x":17,"y":0,"z":10,"name":"cracked_stone_bricks","properties":{}},{"x":18,"y":0,"z":10,"name":"stone","properties":{}},{"x":19,"y":0,"z":10,"name":"stone_bricks","properties":{}},{"x":20,"y":0,"z":10,"name":"cracked_stone_bricks","properties":{}},{"x":21,"y":0,"z":10,"name":"cracked_stone_bricks","properties":{}},{"x":22,"y":0,"z":10,"name":"cracked_stone_bricks","properties":{}},{"x":23,"y":0,"z":10,"name":"stone_bricks","properties":{}},{"x":27,"y":0,"z":10,"name":"dark_oak_fence","properties":{"east":"false","waterlogged":"false","south":"true","north":"true","west":"false"}},{"x":6,"y":0,"z":11,"name":"oak_leaves","properties":{"waterlogged":"false","distance":"2","persistent":"true"}},{"x":7,"y":0,"z":11,"name":"cracked_stone_bricks","properties":{}},{"x":8,"y":0,"z":11,"name":"furnace","properties":{"lit":"false","facing":"east"},"nbt":{"CookTime":0,"BurnTime":0,"x":8,"y":0,"Items":[],"z":11,"id":"minecraft:furnace","CookTimeTotal":0,"RecipesUsed":{}}},{"x":22,"y":0,"z":11,"name":"chest","properties":{"waterlogged":"false","facing":"west","type":"right"},"nbt":{"x":22,"y":0,"Items":[],"z":11,"id":"minecraft:chest"}},{"x":23,"y":0,"z":11,"name":"cracked_stone_bricks","properties":{}},{"x":27,"y":0,"z":11,"name":"dark_oak_fence_gate","properties":{"in_wall":"false","powered":"false","facing":"west","open":"false"}},{"x":6,"y":0,"z":12,"name":"oak_leaves","properties":{"waterlogged":"false","distance":"3","persistent":"true"}},{"x":7,"y":0,"z":12,"name":"cracked_stone_bricks","properties":{}},{"x":8,"y":0,"z":12,"name":"furnace","properties":{"lit":"false","facing":"east"},"nbt":{"CookTime":0,"BurnTime":0,"x":8,"y":0,"Items":[],"z":12,"id":"minecraft:furnace","CookTimeTotal":0,"RecipesUsed":{}}},{"x":11,"y":0,"z":12,"name":"brown_carpet","properties":{}},{"x":12,"y":0,"z":12,"name":"brown_carpet","properties":{}},{"x":13,"y":0,"z":12,"name":"brown_carpet","properties":{}},{"x":14,"y":0,"z":12,"name":"brown_carpet","properties":{}},{"x":15,"y":0,"z":12,"name":"brown_carpet","properties":{}},{"x":16,"y":0,"z":12,"name":"brown_carpet","properties":{}},{"x":17,"y":0,"z":12,"name":"brown_carpet","properties":{}},{"x":18,"y":0,"z":12,"name":"brown_carpet","properties":{}},{"x":19,"y":0,"z":12,"name":"brown_carpet","properties":{}},{"x":22,"y":0,"z":12,"name":"chest","properties":{"waterlogged":"false","facing":"west","type":"left"},"nbt":{"x":22,"y":0,"Items":[],"z":12,"id":"minecraft:chest"}},{"x":23,"y":0,"z":12,"name":"stone_bricks","properties":{}},{"x":24,"y":0,"z":12,"name":"stone_brick_stairs","properties":{"half":"bottom","waterlogged":"true","shape":"inner_right","facing":"north"}},{"x":27,"y":0,"z":12,"name":"dark_oak_fence_gate","properties":{"in_wall":"false","powered":"false","facing":"west","open":"false"}},{"x":6,"y":0,"z":13,"name":"oak_leaves","properties":{"waterlogged":"false","distance":"4","persistent":"true"}},{"x":7,"y":0,"z":13,"name":"cracked_stone_bricks","properties":{}},{"x":8,"y":0,"z":13,"name":"anvil","properties":{"facing":"north"}},{"x":10,"y":0,"z":13,"name":"brown_carpet","properties":{}},{"x":11,"y":0,"z":13,"name":"brown_carpet","properties":{}},{"x":12,"y":0,"z":13,"name":"brown_carpet","properties":{}},{"x":13,"y":0,"z":13,"name":"brown_carpet","properties":{}},{"x":14,"y":0,"z":13,"name":"brown_carpet","properties":{}},{"x":15,"y":0,"z":13,"name":"brown_carpet","properties":{}},{"x":16,"y":0,"z":13,"name":"brown_carpet","properties":{}},{"x":17,"y":0,"z":13,"name":"brown_carpet","properties":{}},{"x":18,"y":0,"z":13,"name":"brown_carpet","properties":{}},{"x":19,"y":0,"z":13,"name":"brown_carpet","properties":{}},{"x":20,"y":0,"z":13,"name":"brown_carpet","properties":{}},{"x":22,"y":0,"z":13,"name":"chest","properties":{"waterlogged":"false","facing":"west","type":"right"},"nbt":{"x":22,"y":0,"Items":[],"z":13,"id":"minecraft:chest"}},{"x":23,"y":0,"z":13,"name":"cracked_stone_bricks","properties":{}},{"x":24,"y":0,"z":13,"name":"stone_brick_stairs","properties":{"half":"bottom","waterlogged":"true","shape":"straight","facing":"east"}},{"x":27,"y":0,"z":13,"name":"dark_oak_fence_gate","properties":{"in_wall":"false","powered":"false","facing":"west","open":"false"}},{"x":6,"y":0,"z":14,"name":"oak_leaves","properties":{"waterlogged":"false","distance":"5","persistent":"true"}},{"x":7,"y":0,"z":14,"name":"cobblestone_wall","properties":{"east":"none","waterlogged":"false","south":"tall","north":"tall","west":"none","up":"false"}},{"x":8,"y":0,"z":14,"name":"anvil","properties":{"facing":"north"}},{"x":11,"y":0,"z":14,"name":"brown_carpet","properties":{}},{"x":12,"y":0,"z":14,"name":"brown_carpet","properties":{}},{"x":13,"y":0,"z":14,"name":"brown_carpet","properties":{}},{"x":14,"y":0,"z":14,"name":"brown_carpet","properties":{}},{"x":15,"y":0,"z":14,"name":"brown_carpet","properties":{}},{"x":16,"y":0,"z":14,"name":"brown_carpet","properties":{}},{"x":17,"y":0,"z":14,"name":"brown_carpet","properties":{}},{"x":18,"y":0,"z":14,"name":"brown_carpet","properties":{}},{"x":19,"y":0,"z":14,"name":"brown_carpet","properties":{}},{"x":22,"y":0,"z":14,"name":"chest","properties":{"waterlogged":"false","facing":"west","type":"left"},"nbt":{"x":22,"y":0,"Items":[],"z":14,"id":"minecraft:chest"}},{"x":23,"y":0,"z":14,"name":"stone","properties":{}},{"x":24,"y":0,"z":14,"name":"stone_brick_stairs","properties":{"half":"bottom","waterlogged":"true","shape":"straight","facing":"east"}},{"x":27,"y":0,"z":14,"name":"dark_oak_fence","properties":{"east":"false","waterlogged":"false","south":"true","north":"true","west":"false"}},{"x":6,"y":0,"z":15,"name":"oak_leaves","properties":{"waterlogged":"false","distance":"4","persistent":"true"}},{"x":7,"y":0,"z":15,"name":"cobblestone_wall","properties":{"east":"none","waterlogged":"false","south":"tall","north":"tall","west":"none","up":"false"}},{"x":8,"y":0,"z":15,"name":"dark_oak_stairs","properties":{"half":"top","waterlogged":"false","shape":"straight","facing":"north"}},{"x":16,"y":0,"z":15,"name":"spruce_trapdoor","properties":{"half":"top","waterlogged":"false","powered":"false","facing":"north","open":"true"}},{"x":17,"y":0,"z":15,"name":"spruce_trapdoor","properties":{"half":"top","waterlogged":"false","powered":"false","facing":"north","open":"true"}},{"x":22,"y":0,"z":15,"name":"chest","properties":{"waterlogged":"false","facing":"west","type":"right"},"nbt":{"x":22,"y":0,"Items":[],"z":15,"id":"minecraft:chest"}},{"x":23,"y":0,"z":15,"name":"cobblestone_wall","properties":{"east":"tall","waterlogged":"false","south":"tall","north":"tall","west":"none","up":"true"}},{"x":24,"y":0,"z":15,"name":"stripped_spruce_log","properties":{"axis":"y"}},{"x":25,"y":0,"z":15,"name":"barrel","properties":{"facing":"north","open":"false"},"nbt":{"x":25,"y":0,"Items":[],"z":15,"id":"minecraft:barrel"}},{"x":26,"y":0,"z":15,"name":"barrel","properties":{"facing":"north","open":"false"},"nbt":{"x":26,"y":0,"Items":[],"z":15,"id":"minecraft:barrel"}},{"x":27,"y":0,"z":15,"name":"stripped_spruce_log","properties":{"axis":"y"}},{"x":28,"y":0,"z":15,"name":"dark_oak_wall_sign","properties":{"waterlogged":"false","facing":"east"},"nbt":{"back_text":{"has_glowing_text":0,"color":"black","messages":["\"\"","\"\"","\"\"","\"\""]},"is_waxed":0,"x":28,"y":0,"z":15,"id":"minecraft:sign","front_text":{"has_glowing_text":0,"color":"black","messages":["\"\"","\"\"","\"\"","\"\""]}}},{"x":6,"y":0,"z":16,"name":"oak_leaves","properties":{"waterlogged":"false","distance":"3","persistent":"true"}},{"x":7,"y":0,"z":16,"name":"cobblestone","properties":{}},{"x":8,"y":0,"z":16,"name":"dark_oak_stairs","properties":{"half":"top","waterlogged":"false","shape":"straight","facing":"south"}},{"x":16,"y":0,"z":16,"name":"polished_deepslate_stairs","properties":{"half":"top","waterlogged":"false","shape":"straight","facing":"east"}},{"x":17,"y":0,"z":16,"name":"polished_deepslate_stairs","properties":{"half":"bottom","waterlogged":"false","shape":"straight","facing":"west"}},{"x":22,"y":0,"z":16,"name":"chest","properties":{"waterlogged":"false","facing":"west","type":"left"},"nbt":{"x":22,"y":0,"Items":[],"z":16,"id":"minecraft:chest"}},{"x":23,"y":0,"z":16,"name":"cobblestone","properties":{}},{"x":24,"y":0,"z":16,"name":"stripped_spruce_log","properties":{"axis":"y"}},{"x":25,"y":0,"z":16,"name":"stripped_spruce_log","properties":{"axis":"y"}},{"x":26,"y":0,"z":16,"name":"stripped_spruce_log","properties":{"axis":"y"}},{"x":27,"y":0,"z":16,"name":"spruce_stairs","properties":{"half":"top","waterlogged":"false","shape":"straight","facing":"west"}},{"x":28,"y":0,"z":16,"name":"dark_oak_wall_sign","properties":{"waterlogged":"false","facing":"east"},"nbt":{"back_text":{"has_glowing_text":0,"color":"black","messages":["\"\"","\"\"","\"\"","\"\""]},"is_waxed":0,"x":28,"y":0,"z":16,"id":"minecraft:sign","front_text":{"has_glowing_text":0,"color":"black","messages":["\"\"","\"\"","\"\"","\"\""]}}},{"x":6,"y":0,"z":17,"name":"oak_leaves","properties":{"waterlogged":"false","distance":"2","persistent":"true"}},{"x":7,"y":0,"z":17,"name":"cobblestone","properties":{}},{"x":8,"y":0,"z":17,"name":"dark_oak_planks","properties":{}},{"x":12,"y":0,"z":17,"name":"dark_oak_fence","properties":{"east":"true","waterlogged":"false","south":"true","north":"false","west":"false"}},{"x":13,"y":0,"z":17,"name":"stripped_dark_oak_wood","properties":{"axis":"y"}},{"x":16,"y":0,"z":17,"name":"polished_deepslate_stairs","properties":{"half":"top","waterlogged":"false","shape":"straight","facing":"east"}},{"x":17,"y":0,"z":17,"name":"polished_deepslate_stairs","properties":{"half":"bottom","waterlogged":"false","shape":"straight","facing":"west"}},{"x":19,"y":0,"z":17,"name":"spruce_trapdoor","properties":{"half":"bottom","waterlogged":"false","powered":"false","facing":"north","open":"true"}},{"x":21,"y":0,"z":17,"name":"spruce_trapdoor","properties":{"half":"bottom","waterlogged":"false","powered":"false","facing":"north","open":"true"}},{"x":22,"y":0,"z":17,"name":"crafting_table","properties":{}},{"x":23,"y":0,"z":17,"name":"stone_bricks","properties":{}},{"x":24,"y":0,"z":17,"name":"stripped_spruce_log","properties":{"axis":"y"}},{"x":27,"y":0,"z":17,"name":"spruce_stairs","properties":{"half":"top","waterlogged":"false","shape":"straight","facing":"west"}},{"x":28,"y":0,"z":17,"name":"dark_oak_wall_sign","properties":{"waterlogged":"false","facing":"east"},"nbt":{"back_text":{"has_glowing_text":0,"color":"black","messages":["\"\"","\"\"","\"\"","\"\""]},"is_waxed":0,"x":28,"y":0,"z":17,"id":"minecraft:sign","front_text":{"has_glowing_text":0,"color":"black","messages":["\"\"","\"\"","\"\"","\"\""]}}},{"x":6,"y":0,"z":18,"name":"oak_leaves","properties":{"waterlogged":"false","distance":"1","persistent":"true"}},{"x":7,"y":0,"z":18,"name":"stone","properties":{}},{"x":8,"y":0,"z":18,"name":"loom","properties":{"facing":"east"}},{"x":10,"y":0,"z":18,"name":"brown_carpet","properties":{}},{"x":12,"y":0,"z":18,"name":"bookshelf","properties":{}},{"x":13,"y":0,"z":18,"name":"cracked_stone_bricks","properties":{}},{"x":14,"y":0,"z":18,"name":"stone_bricks","properties":{}},{"x":15,"y":0,"z":18,"name":"stone_bricks","properties":{}},{"x":16,"y":0,"z":18,"name":"cracked_stone_bricks","properties":{}},{"x":17,"y":0,"z":18,"name":"cobblestone","properties":{}},{"x":18,"y":0,"z":18,"name":"cracked_stone_bricks","properties":{}},{"x":20,"y":0,"z":18,"name":"spruce_door","properties":{"hinge":"left","half":"lower","powered":"false","facing":"south","open":"true"}},{"x":22,"y":0,"z":18,"name":"cracked_stone_bricks","properties":{}},{"x":23,"y":0,"z":18,"name":"stone_bricks","properties":{}},{"x":24,"y":0,"z":18,"name":"stripped_spruce_log","properties":{"axis":"y"}},{"x":25,"y":0,"z":18,"name":"spruce_stairs","properties":{"half":"top","waterlogged":"false","shape":"straight","facing":"south"}},{"x":26,"y":0,"z":18,"name":"spruce_stairs","properties":{"half":"top","waterlogged":"false","shape":"straight","facing":"south"}},{"x":27,"y":0,"z":18,"name":"spruce_stairs","properties":{"half":"top","waterlogged":"false","shape":"straight","facing":"west"}},{"x":28,"y":0,"z":18,"name":"dark_oak_wall_sign","properties":{"waterlogged":"false","facing":"east"},"nbt":{"back_text":{"has_glowing_text":0,"color":"black","messages":["\"\"","\"\"","\"\"","\"\""]},"is_waxed":0,"x":28,"y":0,"z":18,"id":"minecraft:sign","front_text":{"has_glowing_text":0,"color":"black","messages":["\"\"","\"\"","\"\"","\"\""]}}},{"x":5,"y":0,"z":19,"name":"dark_oak_wall_sign","properties":{"waterlogged":"false","facing":"west"},"nbt":{"back_text":{"has_glowing_text":0,"color":"black","messages":["\"\"","\"\"","\"\"","\"\""]},"is_waxed":0,"x":5,"y":0,"z":19,"id":"minecraft:sign","front_text":{"has_glowing_text":0,"color":"black","messages":["\"\"","\"\"","\"\"","\"\""]}}},{"x":6,"y":0,"z":19,"name":"stripped_spruce_wood","properties":{"axis":"y"}},{"x":7,"y":0,"z":19,"name":"stone","properties":{}},{"x":8,"y":0,"z":19,"name":"dark_oak_stairs","properties":{"half":"top","waterlogged":"false","shape":"straight","facing":"west"}},{"x":9,"y":0,"z":19,"name":"brown_carpet","properties":{}},{"x":10,"y":0,"z":19,"name":"brown_carpet","properties":{}},{"x":11,"y":0,"z":19,"name":"brown_carpet","properties":{}},{"x":12,"y":0,"z":19,"name":"barrel","properties":{"facing":"west","open":"false"},"nbt":{"x":12,"y":0,"Items":[],"z":19,"id":"minecraft:barrel"}},{"x":13,"y":0,"z":19,"name":"cobblestone","properties":{}},{"x":14,"y":0,"z":19,"name":"stripped_spruce_wood","properties":{"axis":"y"}},{"x":15,"y":0,"z":19,"name":"oak_leaves","properties":{"waterlogged":"false","distance":"1","persistent":"true"}},{"x":16,"y":0,"z":19,"name":"oak_leaves","properties":{"waterlogged":"false","distance":"2","persistent":"true"}},{"x":17,"y":0,"z":19,"name":"oak_leaves","properties":{"waterlogged":"false","distance":"3","persistent":"true"}},{"x":18,"y":0,"z":19,"name":"spruce_trapdoor","properties":{"half":"top","waterlogged":"false","powered":"false","facing":"east","open":"true"}},{"x":22,"y":0,"z":19,"name":"spruce_trapdoor","properties":{"half":"top","waterlogged":"false","powered":"false","facing":"west","open":"true"}},{"x":23,"y":0,"z":19,"name":"oak_leaves","properties":{"waterlogged":"false","distance":"1","persistent":"true"}},{"x":24,"y":0,"z":19,"name":"stripped_spruce_wood","properties":{"axis":"y"}},{"x":25,"y":0,"z":19,"name":"spruce_stairs","properties":{"half":"bottom","waterlogged":"false","shape":"straight","facing":"north"}},{"x":26,"y":0,"z":19,"name":"spruce_stairs","properties":{"half":"bottom","waterlogged":"false","shape":"straight","facing":"north"}},{"x":27,"y":0,"z":19,"name":"stripped_spruce_log","properties":{"axis":"y"}},{"x":28,"y":0,"z":19,"name":"dark_oak_wall_sign","properties":{"waterlogged":"false","facing":"east"},"nbt":{"back_text":{"has_glowing_text":0,"color":"black","messages":["\"\"","\"\"","\"\"","\"\""]},"is_waxed":0,"x":28,"y":0,"z":19,"id":"minecraft:sign","front_text":{"has_glowing_text":0,"color":"black","messages":["\"\"","\"\"","\"\"","\"\""]}}},{"x":6,"y":0,"z":20,"name":"oak_leaves","properties":{"waterlogged":"false","distance":"1","persistent":"true"}},{"x":7,"y":0,"z":20,"name":"stone_bricks","properties":{}},{"x":8,"y":0,"z":20,"name":"smoker","properties":{"lit":"false","facing":"east"},"nbt":{"CookTime":0,"BurnTime":0,"x":8,"y":0,"Items":[],"z":20,"id":"minecraft:smoker","CookTimeTotal":0,"RecipesUsed":{}}},{"x":9,"y":0,"z":20,"name":"brown_carpet","properties":{}},{"x":10,"y":0,"z":20,"name":"brown_carpet","properties":{}},{"x":11,"y":0,"z":20,"name":"brown_carpet","properties":{}},{"x":12,"y":0,"z":20,"name":"barrel","properties":{"facing":"west","open":"false"},"nbt":{"x":12,"y":0,"Items":[],"z":20,"id":"minecraft:barrel"}},{"x":13,"y":0,"z":20,"name":"stone","properties":{}},{"x":14,"y":0,"z":20,"name":"oak_leaves","properties":{"waterlogged":"false","distance":"1","persistent":"true"}},{"x":24,"y":0,"z":20,"name":"dark_oak_wall_sign","properties":{"waterlogged":"false","facing":"south"},"nbt":{"back_text":{"has_glowing_text":0,"color":"black","messages":["\"\"","\"\"","\"\"","\"\""]},"is_waxed":0,"x":24,"y":0,"z":20,"id":"minecraft:sign","front_text":{"has_glowing_text":0,"color":"black","messages":["\"\"","\"\"","\"\"","\"\""]}}},{"x":27,"y":0,"z":20,"name":"dark_oak_wall_sign","properties":{"waterlogged":"false","facing":"south"},"nbt":{"back_text":{"has_glowing_text":0,"color":"black","messages":["\"\"","\"\"","\"\"","\"\""]},"is_waxed":0,"x":27,"y":0,"z":20,"id":"minecraft:sign","front_text":{"has_glowing_text":0,"color":"black","messages":["\"\"","\"\"","\"\"","\"\""]}}},{"x":6,"y":0,"z":21,"name":"oak_leaves","properties":{"waterlogged":"false","distance":"2","persistent":"true"}},{"x":7,"y":0,"z":21,"name":"stone_bricks","properties":{}},{"x":8,"y":0,"z":21,"name":"dark_oak_stairs","properties":{"half":"top","waterlogged":"false","shape":"straight","facing":"west"}},{"x":9,"y":0,"z":21,"name":"brown_carpet","properties":{}},{"x":10,"y":0,"z":21,"name":"brown_carpet","properties":{}},{"x":11,"y":0,"z":21,"name":"brown_carpet","properties":{}},{"x":12,"y":0,"z":21,"name":"bookshelf","properties":{}},{"x":13,"y":0,"z":21,"name":"stone_bricks","properties":{}},{"x":14,"y":0,"z":21,"name":"oak_leaves","properties":{"waterlogged":"false","distance":"2","persistent":"true"}},{"x":16,"y":0,"z":21,"name":"cobblestone_wall","properties":{"east":"none","waterlogged":"false","south":"none","north":"none","west":"none","up":"true"}},{"x":6,"y":0,"z":22,"name":"oak_leaves","properties":{"waterlogged":"false","distance":"3","persistent":"true"}},{"x":7,"y":0,"z":22,"name":"cobblestone_wall","properties":{"east":"none","waterlogged":"false","south":"tall","north":"tall","west":"none","up":"false"}},{"x":8,"y":0,"z":22,"name":"dark_oak_wall_sign","properties":{"waterlogged":"false","facing":"south"},"nbt":{"back_text":{"has_glowing_text":0,"color":"black","messages":["\"\"","\"\"","\"\"","\"\""]},"is_waxed":0,"x":8,"y":0,"z":22,"id":"minecraft:sign","front_text":{"has_glowing_text":0,"color":"black","messages":["\"\"","\"\"","\"\"","\"\""]}}},{"x":9,"y":0,"z":22,"name":"brown_carpet","properties":{}},{"x":10,"y":0,"z":22,"name":"brown_carpet","properties":{}},{"x":11,"y":0,"z":22,"name":"brown_carpet","properties":{}},{"x":13,"y":0,"z":22,"name":"cracked_stone_bricks","properties":{}},{"x":14,"y":0,"z":22,"name":"oak_leaves","properties":{"waterlogged":"false","distance":"3","persistent":"true"}},{"x":6,"y":0,"z":23,"name":"oak_leaves","properties":{"waterlogged":"false","distance":"4","persistent":"true"}},{"x":7,"y":0,"z":23,"name":"cobblestone_wall","properties":{"east":"none","waterlogged":"false","south":"tall","north":"tall","west":"none","up":"false"}},{"x":9,"y":0,"z":23,"name":"brown_carpet","properties":{}},{"x":10,"y":0,"z":23,"name":"brown_carpet","properties":{}},{"x":11,"y":0,"z":23,"name":"brown_carpet","properties":{}},{"x":13,"y":0,"z":23,"name":"cobblestone","properties":{}},{"x":14,"y":0,"z":23,"name":"oak_leaves","properties":{"waterlogged":"false","distance":"4","persistent":"true"}},{"x":6,"y":0,"z":24,"name":"oak_leaves","properties":{"waterlogged":"false","distance":"3","persistent":"true"}},{"x":7,"y":0,"z":24,"name":"stone_bricks","properties":{}},{"x":10,"y":0,"z":24,"name":"brown_carpet","properties":{}},{"x":13,"y":0,"z":24,"name":"stone","properties":{}},{"x":14,"y":0,"z":24,"name":"oak_leaves","properties":{"waterlogged":"false","distance":"3","persistent":"true"}},{"x":6,"y":0,"z":25,"name":"oak_leaves","properties":{"waterlogged":"false","distance":"2","persistent":"true"}},{"x":7,"y":0,"z":25,"name":"cracked_stone_bricks","properties":{}},{"x":8,"y":0,"z":25,"name":"spruce_trapdoor","properties":{"half":"bottom","waterlogged":"false","powered":"false","facing":"west","open":"true"}},{"x":9,"y":0,"z":25,"name":"spruce_trapdoor","properties":{"half":"top","waterlogged":"false","powered":"false","facing":"north","open":"false"}},{"x":10,"y":0,"z":25,"name":"spruce_trapdoor","properties":{"half":"top","waterlogged":"false","powered":"false","facing":"north","open":"false"}},{"x":11,"y":0,"z":25,"name":"spruce_trapdoor","properties":{"half":"top","waterlogged":"false","powered":"false","facing":"north","open":"false"}},{"x":12,"y":0,"z":25,"name":"spruce_trapdoor","properties":{"half":"bottom","waterlogged":"false","powered":"false","facing":"east","open":"true"}},{"x":13,"y":0,"z":25,"name":"cracked_stone_bricks","properties":{}},{"x":14,"y":0,"z":25,"name":"oak_leaves","properties":{"waterlogged":"false","distance":"2","persistent":"true"}},{"x":16,"y":0,"z":25,"name":"cobblestone_wall","properties":{"east":"none","waterlogged":"false","south":"none","north":"none","west":"none","up":"true"}},{"x":6,"y":0,"z":26,"name":"oak_leaves","properties":{"waterlogged":"false","distance":"1","persistent":"true"}},{"x":7,"y":0,"z":26,"name":"cracked_stone_bricks","properties":{}},{"x":8,"y":0,"z":26,"name":"stone_bricks","properties":{}},{"x":9,"y":0,"z":26,"name":"stone_bricks","properties":{}},{"x":10,"y":0,"z":26,"name":"stone_bricks","properties":{}},{"x":11,"y":0,"z":26,"name":"cobblestone_wall","properties":{"east":"tall","waterlogged":"false","south":"none","north":"none","west":"tall","up":"false"}},{"x":12,"y":0,"z":26,"name":"stone_bricks","properties":{}},{"x":13,"y":0,"z":26,"name":"stone_bricks","properties":{}},{"x":14,"y":0,"z":26,"name":"oak_leaves","properties":{"waterlogged":"false","distance":"1","persistent":"true"}},{"x":5,"y":0,"z":27,"name":"dark_oak_wall_sign","properties":{"waterlogged":"false","facing":"west"},"nbt":{"back_text":{"has_glowing_text":0,"color":"black","messages":["\"\"","\"\"","\"\"","\"\""]},"is_waxed":0,"x":5,"y":0,"z":27,"id":"minecraft:sign","front_text":{"has_glowing_text":0,"color":"black","messages":["\"\"","\"\"","\"\"","\"\""]}}},{"x":6,"y":0,"z":27,"name":"stripped_spruce_wood","properties":{"axis":"y"}},{"x":7,"y":0,"z":27,"name":"oak_leaves","properties":{"waterlogged":"false","distance":"1","persistent":"true"}},{"x":8,"y":0,"z":27,"name":"oak_leaves","properties":{"waterlogged":"false","distance":"2","persistent":"true"}},{"x":9,"y":0,"z":27,"name":"oak_leaves","properties":{"waterlogged":"false","distance":"3","persistent":"true"}},{"x":10,"y":0,"z":27,"name":"oak_leaves","properties":{"waterlogged":"false","distance":"4","persistent":"true"}},{"x":11,"y":0,"z":27,"name":"oak_leaves","properties":{"waterlogged":"false","distance":"3","persistent":"true"}},{"x":12,"y":0,"z":27,"name":"oak_leaves","properties":{"waterlogged":"false","distance":"2","persistent":"true"}},{"x":13,"y":0,"z":27,"name":"oak_leaves","properties":{"waterlogged":"false","distance":"1","persistent":"true"}},{"x":14,"y":0,"z":27,"name":"stripped_spruce_wood","properties":{"axis":"y"}},{"x":15,"y":0,"z":27,"name":"dark_oak_wall_sign","properties":{"waterlogged":"false","facing":"east"},"nbt":{"back_text":{"has_glowing_text":0,"color":"black","messages":["\"\"","\"\"","\"\"","\"\""]},"is_waxed":0,"x":15,"y":0,"z":27,"id":"minecraft:sign","front_text":{"has_glowing_text":0,"color":"black","messages":["\"\"","\"\"","\"\"","\"\""]}}},{"x":6,"y":0,"z":28,"name":"dark_oak_wall_sign","properties":{"waterlogged":"false","facing":"south"},"nbt":{"back_text":{"has_glowing_text":0,"color":"black","messages":["\"\"","\"\"","\"\"","\"\""]},"is_waxed":0,"x":6,"y":0,"z":28,"id":"minecraft:sign","front_text":{"has_glowing_text":0,"color":"black","messages":["\"\"","\"\"","\"\"","\"\""]}}},{"x":14,"y":0,"z":28,"name":"dark_oak_wall_sign","properties":{"waterlogged":"false","facing":"south"},"nbt":{"back_text":{"has_glowing_text":0,"color":"black","messages":["\"\"","\"\"","\"\"","\"\""]},"is_waxed":0,"x":14,"y":0,"z":28,"id":"minecraft:sign","front_text":{"has_glowing_text":0,"color":"black","messages":["\"\"","\"\"","\"\"","\"\""]}}},{"x":6,"y":1,"z":6,"name":"stripped_spruce_wood","properties":{"axis":"y"}},{"x":7,"y":1,"z":6,"name":"dark_oak_fence","properties":{"east":"false","waterlogged":"false","south":"true","north":"false","west":"true"}},{"x":13,"y":1,"z":6,"name":"dark_oak_fence","properties":{"east":"true","waterlogged":"false","south":"true","north":"false","west":"false"}},{"x":14,"y":1,"z":6,"name":"stripped_spruce_wood","properties":{"axis":"y"}},{"x":6,"y":1,"z":7,"name":"dark_oak_fence","properties":{"east":"true","waterlogged":"false","south":"false","north":"true","west":"false"}},{"x":7,"y":1,"z":7,"name":"cobblestone","properties":{}},{"x":8,"y":1,"z":7,"name":"stone_bricks","properties":{}},{"x":9,"y":1,"z":7,"name":"glass_pane","properties":{"east":"true","waterlogged":"false","south":"false","north":"false","west":"true"}},{"x":10,"y":1,"z":7,"name":"glass_pane","properties":{"east":"true","waterlogged":"false","south":"false","north":"false","west":"true"}},{"x":11,"y":1,"z":7,"name":"glass_pane","properties":{"east":"true","waterlogged":"false","south":"false","north":"false","west":"true"}},{"x":12,"y":1,"z":7,"name":"stone_bricks","properties":{}},{"x":13,"y":1,"z":7,"name":"stone_bricks","properties":{}},{"x":14,"y":1,"z":7,"name":"dark_oak_fence","properties":{"east":"false","waterlogged":"false","south":"false","north":"true","west":"true"}},{"x":7,"y":1,"z":8,"name":"glass_pane","properties":{"east":"false","waterlogged":"false","south":"true","north":"true","west":"false"}},{"x":9,"y":1,"z":8,"name":"potted_cherry_sapling","properties":{}},{"x":11,"y":1,"z":8,"name":"potted_azalea_bush","properties":{}},{"x":13,"y":1,"z":8,"name":"glass_pane","properties":{"east":"false","waterlogged":"false","south":"true","north":"true","west":"false"}},{"x":6,"y":1,"z":9,"name":"stripped_spruce_wood","properties":{"axis":"y"}},{"x":7,"y":1,"z":9,"name":"stone","properties":{}},{"x":13,"y":1,"z":9,"name":"stone_bricks","properties":{}},{"x":14,"y":1,"z":9,"name":"stripped_spruce_wood","properties":{"axis":"y"}},{"x":15,"y":1,"z":9,"name":"dark_oak_fence","properties":{"east":"false","waterlogged":"false","south":"true","north":"false","west":"true"}},{"x":19,"y":1,"z":9,"name":"dark_oak_fence","properties":{"east":"false","waterlogged":"false","south":"true","north":"false","west":"false"}},{"x":23,"y":1,"z":9,"name":"dark_oak_fence","properties":{"east":"true","waterlogged":"false","south":"true","north":"false","west":"false"}},{"x":24,"y":1,"z":9,"name":"stripped_spruce_wood","properties":{"axis":"y"}},{"x":27,"y":1,"z":9,"name":"stripped_spruce_log","properties":{"axis":"y"}},{"x":6,"y":1,"z":10,"name":"dark_oak_fence","properties":{"east":"true","waterlogged":"false","south":"false","north":"true","west":"false"}},{"x":7,"y":1,"z":10,"name":"stone","properties":{}},{"x":8,"y":1,"z":10,"name":"blast_furnace","properties":{"lit":"false","facing":"east"},"nbt":{"CookTime":0,"BurnTime":0,"x":8,"y":1,"Items":[],"z":10,"id":"minecraft:blast_furnace","CookTimeTotal":0,"RecipesUsed":{}}},{"x":13,"y":1,"z":10,"name":"cracked_stone_bricks","properties":{}},{"x":14,"y":1,"z":10,"name":"stone_bricks","properties":{}},{"x":15,"y":1,"z":10,"name":"cracked_stone_bricks","properties":{}},{"x":16,"y":1,"z":10,"name":"glass_pane","properties":{"east":"true","waterlogged":"false","south":"false","north":"false","west":"true"}},{"x":17,"y":1,"z":10,"name":"glass_pane","properties":{"east":"true","waterlogged":"false","south":"false","north":"false","west":"true"}},{"x":18,"y":1,"z":10,"name":"stone_bricks","properties":{}},{"x":19,"y":1,"z":10,"name":"stone_bricks","properties":{}},{"x":20,"y":1,"z":10,"name":"stone_bricks","properties":{}},{"x":21,"y":1,"z":10,"name":"glass_pane","properties":{"east":"true","waterlogged":"false","south":"false","north":"false","west":"true"}},{"x":22,"y":1,"z":10,"name":"glass_pane","properties":{"east":"true","waterlogged":"false","south":"false","north":"false","west":"true"}},{"x":23,"y":1,"z":10,"name":"stone","properties":{}},{"x":7,"y":1,"z":11,"name":"stone_bricks","properties":{}},{"x":8,"y":1,"z":11,"name":"blast_furnace","properties":{"lit":"false","facing":"east"},"nbt":{"CookTime":0,"BurnTime":0,"x":8,"y":1,"Items":[],"z":11,"id":"minecraft:blast_furnace","CookTimeTotal":0,"RecipesUsed":{}}},{"x":22,"y":1,"z":11,"name":"chest","properties":{"waterlogged":"false","facing":"west","type":"right"},"nbt":{"x":22,"y":1,"Items":[],"z":11,"id":"minecraft:chest"}},{"x":23,"y":1,"z":11,"name":"cobblestone_wall","properties":{"east":"none","waterlogged":"false","south":"tall","north":"tall","west":"none","up":"false"}},{"x":7,"y":1,"z":12,"name":"cobblestone","properties":{}},{"x":8,"y":1,"z":12,"name":"blast_furnace","properties":{"lit":"false","facing":"east"},"nbt":{"CookTime":0,"BurnTime":0,"x":8,"y":1,"Items":[],"z":12,"id":"minecraft:blast_furnace","CookTimeTotal":0,"RecipesUsed":{}}},{"x":22,"y":1,"z":12,"name":"chest","properties":{"waterlogged":"false","facing":"west","type":"left"},"nbt":{"x":22,"y":1,"Items":[],"z":12,"id":"minecraft:chest"}},{"x":23,"y":1,"z":12,"name":"cobblestone_wall","properties":{"east":"none","waterlogged":"false","south":"tall","north":"tall","west":"none","up":"false"}},{"x":7,"y":1,"z":13,"name":"glass_pane","properties":{"east":"false","waterlogged":"false","south":"true","north":"true","west":"false"}},{"x":22,"y":1,"z":13,"name":"chest","properties":{"waterlogged":"false","facing":"west","type":"right"},"nbt":{"x":22,"y":1,"Items":[],"z":13,"id":"minecraft:chest"}},{"x":23,"y":1,"z":13,"name":"stone","properties":{}},{"x":7,"y":1,"z":14,"name":"glass_pane","properties":{"east":"false","waterlogged":"false","south":"true","north":"true","west":"false"}},{"x":22,"y":1,"z":14,"name":"chest","properties":{"waterlogged":"false","facing":"west","type":"left"},"nbt":{"x":22,"y":1,"Items":[],"z":14,"id":"minecraft:chest"}},{"x":23,"y":1,"z":14,"name":"stone","properties":{}},{"x":7,"y":1,"z":15,"name":"glass_pane","properties":{"east":"false","waterlogged":"false","south":"true","north":"true","west":"false"}},{"x":15,"y":1,"z":15,"name":"spruce_trapdoor","properties":{"half":"top","waterlogged":"false","powered":"false","facing":"north","open":"true"}},{"x":16,"y":1,"z":15,"name":"spruce_trapdoor","properties":{"half":"bottom","waterlogged":"false","powered":"false","facing":"north","open":"true"}},{"x":22,"y":1,"z":15,"name":"chest","properties":{"waterlogged":"false","facing":"west","type":"right"},"nbt":{"x":22,"y":1,"Items":[],"z":15,"id":"minecraft:chest"}},{"x":23,"y":1,"z":15,"name":"cobblestone","properties":{}},{"x":24,"y":1,"z":15,"name":"stripped_spruce_log","properties":{"axis":"y"}},{"x":25,"y":1,"z":15,"name":"barrel","properties":{"facing":"north","open":"false"},"nbt":{"x":25,"y":1,"Items":[],"z":15,"id":"minecraft:barrel"}},{"x":26,"y":1,"z":15,"name":"barrel","properties":{"facing":"north","open":"false"},"nbt":{"x":26,"y":1,"Items":[],"z":15,"id":"minecraft:barrel"}},{"x":27,"y":1,"z":15,"name":"stripped_spruce_log","properties":{"axis":"y"}},{"x":7,"y":1,"z":16,"name":"stone_bricks","properties":{}},{"x":8,"y":1,"z":16,"name":"barrel","properties":{"facing":"east","open":"false"},"nbt":{"x":8,"y":1,"Items":[],"z":16,"id":"minecraft:barrel"}},{"x":15,"y":1,"z":16,"name":"polished_deepslate_stairs","properties":{"half":"top","waterlogged":"false","shape":"straight","facing":"east"}},{"x":16,"y":1,"z":16,"name":"polished_deepslate_stairs","properties":{"half":"bottom","waterlogged":"false","shape":"straight","facing":"west"}},{"x":22,"y":1,"z":16,"name":"chest","properties":{"waterlogged":"false","facing":"west","type":"left"},"nbt":{"x":22,"y":1,"Items":[],"z":16,"id":"minecraft:chest"}},{"x":23,"y":1,"z":16,"name":"cracked_stone_bricks","properties":{}},{"x":24,"y":1,"z":16,"name":"stripped_spruce_log","properties":{"axis":"y"}},{"x":25,"y":1,"z":16,"name":"stripped_spruce_log","properties":{"axis":"y"}},{"x":26,"y":1,"z":16,"name":"stripped_spruce_log","properties":{"axis":"y"}},{"x":27,"y":1,"z":16,"name":"stripped_spruce_log","properties":{"axis":"y"}},{"x":7,"y":1,"z":17,"name":"stone_bricks","properties":{}},{"x":8,"y":1,"z":17,"name":"dark_oak_planks","properties":{}},{"x":12,"y":1,"z":17,"name":"dark_oak_fence","properties":{"east":"true","waterlogged":"false","south":"true","north":"false","west":"false"}},{"x":13,"y":1,"z":17,"name":"stripped_dark_oak_wood","properties":{"axis":"y"}},{"x":15,"y":1,"z":17,"name":"polished_deepslate_stairs","properties":{"half":"top","waterlogged":"false","shape":"straight","facing":"east"}},{"x":16,"y":1,"z":17,"name":"polished_deepslate_stairs","properties":{"half":"bottom","waterlogged":"false","shape":"straight","facing":"west"}},{"x":19,"y":1,"z":17,"name":"spruce_trapdoor","properties":{"half":"bottom","waterlogged":"false","powered":"false","facing":"north","open":"true"}},{"x":21,"y":1,"z":17,"name":"spruce_trapdoor","properties":{"half":"bottom","waterlogged":"false","powered":"false","facing":"north","open":"true"}},{"x":22,"y":1,"z":17,"name":"crafting_table","properties":{}},{"x":23,"y":1,"z":17,"name":"stone_bricks","properties":{}},{"x":24,"y":1,"z":17,"name":"stripped_spruce_log","properties":{"axis":"y"}},{"x":25,"y":1,"z":17,"name":"spruce_stairs","properties":{"half":"top","waterlogged":"false","shape":"straight","facing":"south"}},{"x":26,"y":1,"z":17,"name":"spruce_stairs","properties":{"half":"top","waterlogged":"false","shape":"straight","facing":"south"}},{"x":27,"y":1,"z":17,"name":"stripped_spruce_log","properties":{"axis":"y"}},{"x":6,"y":1,"z":18,"name":"dark_oak_fence","properties":{"east":"true","waterlogged":"false","south":"true","north":"false","west":"false"}},{"x":7,"y":1,"z":18,"name":"stone","properties":{}},{"x":11,"y":1,"z":18,"name":"ladder","properties":{"waterlogged":"false","facing":"west"}},{"x":12,"y":1,"z":18,"name":"bookshelf","properties":{}},{"x":13,"y":1,"z":18,"name":"cracked_stone_bricks","properties":{}},{"x":14,"y":1,"z":18,"name":"stone_bricks","properties":{}},{"x":15,"y":1,"z":18,"name":"stone","properties":{}},{"x":16,"y":1,"z":18,"name":"cracked_stone_bricks","properties":{}},{"x":17,"y":1,"z":18,"name":"stone_bricks","properties":{}},{"x":18,"y":1,"z":18,"name":"cobblestone","properties":{}},{"x":20,"y":1,"z":18,"name":"spruce_door","properties":{"hinge":"left","half":"upper","powered":"false","facing":"south","open":"true"}},{"x":22,"y":1,"z":18,"name":"stone_bricks","properties":{}},{"x":23,"y":1,"z":18,"name":"cobblestone_wall","properties":{"east":"low","waterlogged":"false","south":"none","north":"tall","west":"tall","up":"true"}},{"x":24,"y":1,"z":18,"name":"stripped_spruce_log","properties":{"axis":"y"}},{"x":25,"y":1,"z":18,"name":"spruce_stairs","properties":{"half":"bottom","waterlogged":"false","shape":"straight","facing":"north"}},{"x":26,"y":1,"z":18,"name":"spruce_stairs","properties":{"half":"bottom","waterlogged":"false","shape":"straight","facing":"north"}},{"x":27,"y":1,"z":18,"name":"stripped_spruce_log","properties":{"axis":"y"}},{"x":6,"y":1,"z":19,"name":"stripped_spruce_wood","properties":{"axis":"y"}},{"x":7,"y":1,"z":19,"name":"stone_bricks","properties":{}},{"x":8,"y":1,"z":19,"name":"brewing_stand","properties":{"has_bottle_0":"false","has_bottle_1":"false","has_bottle_2":"false"},"nbt":{"Fuel":0,"x":8,"y":1,"Items":[],"z":19,"id":"minecraft:brewing_stand","BrewTime":0}},{"x":12,"y":1,"z":19,"name":"barrel","properties":{"facing":"west","open":"false"},"nbt":{"x":12,"y":1,"Items":[],"z":19,"id":"minecraft:barrel"}},{"x":13,"y":1,"z":19,"name":"stone_bricks","properties":{}},{"x":14,"y":1,"z":19,"name":"stripped_spruce_wood","properties":{"axis":"y"}},{"x":15,"y":1,"z":19,"name":"dark_oak_fence","properties":{"east":"false","waterlogged":"false","south":"false","north":"true","west":"true"}},{"x":23,"y":1,"z":19,"name":"dark_oak_fence","properties":{"east":"true","waterlogged":"false","south":"false","north":"false","west":"false"}},{"x":24,"y":1,"z":19,"name":"stripped_spruce_wood","properties":{"axis":"y"}},{"x":27,"y":1,"z":19,"name":"spruce_fence","properties":{"east":"false","waterlogged":"false","south":"false","north":"true","west":"false"}},{"x":6,"y":1,"z":20,"name":"dark_oak_fence","properties":{"east":"true","waterlogged":"false","south":"false","north":"true","west":"false"}},{"x":7,"y":1,"z":20,"name":"cracked_stone_bricks","properties":{}},{"x":8,"y":1,"z":20,"name":"cobblestone_wall","properties":{"east":"none","waterlogged":"false","south":"none","north":"none","west":"tall","up":"true"}},{"x":12,"y":1,"z":20,"name":"barrel","properties":{"facing":"west","open":"false"},"nbt":{"x":12,"y":1,"Items":[],"z":20,"id":"minecraft:barrel"}},{"x":13,"y":1,"z":20,"name":"stone_bricks","properties":{}},{"x":14,"y":1,"z":20,"name":"dark_oak_fence","properties":{"east":"false","waterlogged":"false","south":"false","north":"true","west":"true"}},{"x":7,"y":1,"z":21,"name":"stone","properties":{}},{"x":12,"y":1,"z":21,"name":"bookshelf","properties":{}},{"x":13,"y":1,"z":21,"name":"stone","properties":{}},{"x":16,"y":1,"z":21,"name":"dark_oak_fence","properties":{"east":"false","waterlogged":"false","south":"false","north":"false","west":"false"}},{"x":7,"y":1,"z":22,"name":"glass_pane","properties":{"east":"false","waterlogged":"false","south":"true","north":"true","west":"false"}},{"x":13,"y":1,"z":22,"name":"glass_pane","properties":{"east":"false","waterlogged":"false","south":"true","north":"true","west":"false"}},{"x":7,"y":1,"z":23,"name":"glass_pane","properties":{"east":"false","waterlogged":"false","south":"true","north":"true","west":"false"}},{"x":13,"y":1,"z":23,"name":"glass_pane","properties":{"east":"false","waterlogged":"false","south":"true","north":"true","west":"false"}},{"x":7,"y":1,"z":24,"name":"glass_pane","properties":{"east":"false","waterlogged":"false","south":"true","north":"true","west":"false"}},{"x":13,"y":1,"z":24,"name":"glass_pane","properties":{"east":"false","waterlogged":"false","south":"true","north":"true","west":"false"}},{"x":7,"y":1,"z":25,"name":"stone_bricks","properties":{}},{"x":9,"y":1,"z":25,"name":"lantern","properties":{"waterlogged":"false","hanging":"false"}},{"x":11,"y":1,"z":25,"name":"potted_cherry_sapling","properties":{}},{"x":13,"y":1,"z":25,"name":"cobblestone_wall","properties":{"east":"none","waterlogged":"false","south":"tall","north":"tall","west":"none","up":"false"}},{"x":16,"y":1,"z":25,"name":"dark_oak_fence","properties":{"east":"false","waterlogged":"false","south":"false","north":"false","west":"false"}},{"x":6,"y":1,"z":26,"name":"dark_oak_fence","properties":{"east":"true","waterlogged":"false","south":"true","north":"false","west":"false"}},{"x":7,"y":1,"z":26,"name":"cobblestone","properties":{}},{"x":8,"y":1,"z":26,"name":"cracked_stone_bricks","properties":{}},{"x":9,"y":1,"z":26,"name":"glass_pane","properties":{"east":"true","waterlogged":"false","south":"false","north":"false","west":"true"}},{"x":10,"y":1,"z":26,"name":"glass_pane","properties":{"east":"true","waterlogged":"false","south":"false","north":"false","west":"true"}},{"x":11,"y":1,"z":26,"name":"glass_pane","properties":{"east":"true","waterlogged":"false","south":"false","north":"false","west":"true"}},{"x":12,"y":1,"z":26,"name":"stone","properties":{}},{"x":13,"y":1,"z":26,"name":"cobblestone","properties":{}},{"x":14,"y":1,"z":26,"name":"dark_oak_fence","properties":{"east":"false","waterlogged":"false","south":"true","north":"false","west":"true"}},{"x":6,"y":1,"z":27,"name":"stripped_spruce_wood","properties":{"axis":"y"}},{"x":7,"y":1,"z":27,"name":"dark_oak_fence","properties":{"east":"false","waterlogged":"false","south":"false","north":"true","west":"true"}},{"x":8,"y":1,"z":27,"name":"spruce_trapdoor","properties":{"half":"top","waterlogged":"false","powered":"false","facing":"south","open":"true"}},{"x":12,"y":1,"z":27,"name":"spruce_trapdoor","properties":{"half":"top","waterlogged":"false","powered":"false","facing":"south","open":"true"}},{"x":13,"y":1,"z":27,"name":"dark_oak_fence","properties":{"east":"true","waterlogged":"false","south":"false","north":"true","west":"false"}},{"x":14,"y":1,"z":27,"name":"stripped_spruce_wood","properties":{"axis":"y"}},{"x":6,"y":2,"z":6,"name":"stripped_spruce_wood","properties":{"axis":"y"}},{"x":7,"y":2,"z":6,"name":"dark_oak_fence","properties":{"east":"false","waterlogged":"false","south":"true","north":"false","west":"true"}},{"x":13,"y":2,"z":6,"name":"dark_oak_fence","properties":{"east":"true","waterlogged":"false","south":"true","north":"false","west":"false"}},{"x":14,"y":2,"z":6,"name":"stripped_spruce_wood","properties":{"axis":"y"}},{"x":6,"y":2,"z":7,"name":"dark_oak_fence","properties":{"east":"true","waterlogged":"false","south":"false","north":"true","west":"false"}},{"x":7,"y":2,"z":7,"name":"cracked_stone_bricks","properties":{}},{"x":8,"y":2,"z":7,"name":"cracked_stone_bricks","properties":{}},{"x":9,"y":2,"z":7,"name":"glass_pane","properties":{"east":"true","waterlogged":"false","south":"false","north":"false","west":"true"}},{"x":10,"y":2,"z":7,"name":"glass_pane","properties":{"east":"true","waterlogged":"false","south":"false","north":"false","west":"true"}},{"x":11,"y":2,"z":7,"name":"glass_pane","properties":{"east":"true","waterlogged":"false","south":"false","north":"false","west":"true"}},{"x":12,"y":2,"z":7,"name":"cobblestone","properties":{}},{"x":13,"y":2,"z":7,"name":"cobblestone","properties":{}},{"x":14,"y":2,"z":7,"name":"dark_oak_fence","properties":{"east":"false","waterlogged":"false","south":"false","north":"true","west":"true"}},{"x":7,"y":2,"z":8,"name":"glass_pane","properties":{"east":"false","waterlogged":"false","south":"true","north":"true","west":"false"}},{"x":8,"y":2,"z":8,"name":"lantern","properties":{"waterlogged":"false","hanging":"true"}},{"x":12,"y":2,"z":8,"name":"lantern","properties":{"waterlogged":"false","hanging":"true"}},{"x":13,"y":2,"z":8,"name":"glass_pane","properties":{"east":"false","waterlogged":"false","south":"true","north":"true","west":"false"}},{"x":6,"y":2,"z":9,"name":"stripped_spruce_wood","properties":{"axis":"y"}},{"x":7,"y":2,"z":9,"name":"cracked_stone_bricks","properties":{}},{"x":13,"y":2,"z":9,"name":"stone_bricks","properties":{}},{"x":14,"y":2,"z":9,"name":"stripped_spruce_wood","properties":{"axis":"y"}},{"x":15,"y":2,"z":9,"name":"dark_oak_fence","properties":{"east":"false","waterlogged":"false","south":"true","north":"false","west":"true"}},{"x":19,"y":2,"z":9,"name":"dark_oak_fence","properties":{"east":"false","waterlogged":"false","south":"true","north":"false","west":"false"}},{"x":23,"y":2,"z":9,"name":"dark_oak_fence","properties":{"east":"true","waterlogged":"false","south":"true","north":"false","west":"false"}},{"x":24,"y":2,"z":9,"name":"stripped_spruce_wood","properties":{"axis":"y"}},{"x":27,"y":2,"z":9,"name":"stripped_spruce_log","properties":{"axis":"y"}},{"x":6,"y":2,"z":10,"name":"dark_oak_fence","properties":{"east":"true","waterlogged":"false","south":"false","north":"true","west":"false"}},{"x":7,"y":2,"z":10,"name":"cobblestone","properties":{}},{"x":8,"y":2,"z":10,"name":"blast_furnace","properties":{"lit":"false","facing":"east"},"nbt":{"CookTime":0,"BurnTime":0,"x":8,"y":2,"Items":[],"z":10,"id":"minecraft:blast_furnace","CookTimeTotal":0,"RecipesUsed":{}}},{"x":13,"y":2,"z":10,"name":"cracked_stone_bricks","properties":{}},{"x":14,"y":2,"z":10,"name":"stone","properties":{}},{"x":15,"y":2,"z":10,"name":"stone","properties":{}},{"x":16,"y":2,"z":10,"name":"glass_pane","properties":{"east":"true","waterlogged":"false","south":"false","north":"false","west":"true"}},{"x":17,"y":2,"z":10,"name":"glass_pane","properties":{"east":"true","waterlogged":"false","south":"false","north":"false","west":"true"}},{"x":18,"y":2,"z":10,"name":"cobblestone","properties":{}},{"x":19,"y":2,"z":10,"name":"cobblestone","properties":{}},{"x":20,"y":2,"z":10,"name":"stone","properties":{}},{"x":21,"y":2,"z":10,"name":"glass_pane","properties":{"east":"true","waterlogged":"false","south":"false","north":"false","west":"true"}},{"x":22,"y":2,"z":10,"name":"glass_pane","properties":{"east":"true","waterlogged":"false","south":"false","north":"false","west":"true"}},{"x":23,"y":2,"z":10,"name":"cracked_stone_bricks","properties":{}},{"x":27,"y":2,"z":10,"name":"spruce_trapdoor","properties":{"half":"top","waterlogged":"false","powered":"false","facing":"south","open":"true"}},{"x":7,"y":2,"z":11,"name":"cracked_stone_bricks","properties":{}},{"x":8,"y":2,"z":11,"name":"blast_furnace","properties":{"lit":"false","facing":"east"},"nbt":{"CookTime":0,"BurnTime":0,"x":8,"y":2,"Items":[],"z":11,"id":"minecraft:blast_furnace","CookTimeTotal":0,"RecipesUsed":{}}},{"x":18,"y":2,"z":11,"name":"lantern","properties":{"waterlogged":"false","hanging":"true"}},{"x":22,"y":2,"z":11,"name":"chest","properties":{"waterlogged":"false","facing":"west","type":"right"},"nbt":{"x":22,"y":2,"Items":[],"z":11,"id":"minecraft:chest"}},{"x":23,"y":2,"z":11,"name":"cracked_stone_bricks","properties":{}},{"x":7,"y":2,"z":12,"name":"stone_bricks","properties":{}},{"x":8,"y":2,"z":12,"name":"blast_furnace","properties":{"lit":"false","facing":"east"},"nbt":{"CookTime":0,"BurnTime":0,"x":8,"y":2,"Items":[],"z":12,"id":"minecraft:blast_furnace","CookTimeTotal":0,"RecipesUsed":{}}},{"x":22,"y":2,"z":12,"name":"chest","properties":{"waterlogged":"false","facing":"west","type":"left"},"nbt":{"x":22,"y":2,"Items":[],"z":12,"id":"minecraft:chest"}},{"x":23,"y":2,"z":12,"name":"stone","properties":{}},{"x":7,"y":2,"z":13,"name":"glass_pane","properties":{"east":"false","waterlogged":"false","south":"true","north":"true","west":"false"}},{"x":22,"y":2,"z":13,"name":"chest","properties":{"waterlogged":"false","facing":"west","type":"right"},"nbt":{"x":22,"y":2,"Items":[],"z":13,"id":"minecraft:chest"}},{"x":23,"y":2,"z":13,"name":"stone","properties":{}},{"x":7,"y":2,"z":14,"name":"glass_pane","properties":{"east":"false","waterlogged":"false","south":"true","north":"true","west":"false"}},{"x":22,"y":2,"z":14,"name":"chest","properties":{"waterlogged":"false","facing":"west","type":"left"},"nbt":{"x":22,"y":2,"Items":[],"z":14,"id":"minecraft:chest"}},{"x":23,"y":2,"z":14,"name":"cobblestone","properties":{}},{"x":27,"y":2,"z":14,"name":"spruce_trapdoor","properties":{"half":"bottom","waterlogged":"false","powered":"false","facing":"north","open":"true"}},{"x":7,"y":2,"z":15,"name":"glass_pane","properties":{"east":"false","waterlogged":"false","south":"true","north":"true","west":"false"}},{"x":14,"y":2,"z":15,"name":"spruce_trapdoor","properties":{"half":"top","waterlogged":"false","powered":"false","facing":"north","open":"true"}},{"x":15,"y":2,"z":15,"name":"spruce_trapdoor","properties":{"half":"bottom","waterlogged":"false","powered":"false","facing":"north","open":"true"}},{"x":22,"y":2,"z":15,"name":"chest","properties":{"waterlogged":"false","facing":"west","type":"right"},"nbt":{"x":22,"y":2,"Items":[],"z":15,"id":"minecraft:chest"}},{"x":23,"y":2,"z":15,"name":"stone_bricks","properties":{}},{"x":24,"y":2,"z":15,"name":"stripped_spruce_log","properties":{"axis":"y"}},{"x":25,"y":2,"z":15,"name":"barrel","properties":{"facing":"north","open":"false"},"nbt":{"x":25,"y":2,"Items":[],"z":15,"id":"minecraft:barrel"}},{"x":26,"y":2,"z":15,"name":"barrel","properties":{"facing":"north","open":"false"},"nbt":{"x":26,"y":2,"Items":[],"z":15,"id":"minecraft:barrel"}},{"x":27,"y":2,"z":15,"name":"stripped_spruce_log","properties":{"axis":"y"}},{"x":7,"y":2,"z":16,"name":"cobblestone_wall","properties":{"east":"tall","waterlogged":"false","south":"tall","north":"tall","west":"none","up":"true"}},{"x":8,"y":2,"z":16,"name":"barrel","properties":{"facing":"east","open":"false"},"nbt":{"x":8,"y":2,"Items":[],"z":16,"id":"minecraft:barrel"}},{"x":14,"y":2,"z":16,"name":"polished_deepslate_stairs","properties":{"half":"top","waterlogged":"false","shape":"straight","facing":"east"}},{"x":15,"y":2,"z":16,"name":"polished_deepslate_stairs","properties":{"half":"bottom","waterlogged":"false","shape":"straight","facing":"west"}},{"x":22,"y":2,"z":16,"name":"chest","properties":{"waterlogged":"false","facing":"west","type":"left"},"nbt":{"x":22,"y":2,"Items":[],"z":16,"id":"minecraft:chest"}},{"x":23,"y":2,"z":16,"name":"stone_bricks","properties":{}},{"x":24,"y":2,"z":16,"name":"stripped_spruce_log","properties":{"axis":"y"}},{"x":25,"y":2,"z":16,"name":"stripped_spruce_log","properties":{"axis":"y"}},{"x":26,"y":2,"z":16,"name":"stripped_spruce_log","properties":{"axis":"y"}},{"x":27,"y":2,"z":16,"name":"stripped_spruce_log","properties":{"axis":"y"}},{"x":7,"y":2,"z":17,"name":"cracked_stone_bricks","properties":{}},{"x":8,"y":2,"z":17,"name":"dark_oak_planks","properties":{}},{"x":9,"y":2,"z":17,"name":"lantern","properties":{"waterlogged":"false","hanging":"true"}},{"x":12,"y":2,"z":17,"name":"dark_oak_fence","properties":{"east":"true","waterlogged":"false","south":"true","north":"false","west":"false"}},{"x":13,"y":2,"z":17,"name":"stripped_dark_oak_wood","properties":{"axis":"y"}},{"x":14,"y":2,"z":17,"name":"polished_deepslate_stairs","properties":{"half":"top","waterlogged":"false","shape":"straight","facing":"east"}},{"x":15,"y":2,"z":17,"name":"polished_deepslate_stairs","properties":{"half":"bottom","waterlogged":"false","shape":"straight","facing":"west"}},{"x":19,"y":2,"z":17,"name":"spruce_trapdoor","properties":{"half":"bottom","waterlogged":"false","powered":"false","facing":"north","open":"true"}},{"x":20,"y":2,"z":17,"name":"spruce_trapdoor","properties":{"half":"bottom","waterlogged":"false","powered":"false","facing":"north","open":"true"}},{"x":21,"y":2,"z":17,"name":"spruce_trapdoor","properties":{"half":"bottom","waterlogged":"false","powered":"false","facing":"north","open":"true"}},{"x":22,"y":2,"z":17,"name":"lantern","properties":{"waterlogged":"false","hanging":"false"}},{"x":23,"y":2,"z":17,"name":"cobblestone","properties":{}},{"x":24,"y":2,"z":17,"name":"stripped_spruce_log","properties":{"axis":"y"}},{"x":25,"y":2,"z":17,"name":"spruce_stairs","properties":{"half":"bottom","waterlogged":"false","shape":"straight","facing":"north"}},{"x":26,"y":2,"z":17,"name":"spruce_stairs","properties":{"half":"bottom","waterlogged":"false","shape":"straight","facing":"north"}},{"x":27,"y":2,"z":17,"name":"stripped_spruce_log","properties":{"axis":"y"}},{"x":6,"y":2,"z":18,"name":"dark_oak_fence","properties":{"east":"true","waterlogged":"false","south":"true","north":"false","west":"false"}},{"x":7,"y":2,"z":18,"name":"stone","properties":{}},{"x":12,"y":2,"z":18,"name":"bookshelf","properties":{}},{"x":13,"y":2,"z":18,"name":"cracked_stone_bricks","properties":{}},{"x":14,"y":2,"z":18,"name":"stone","properties":{}},{"x":15,"y":2,"z":18,"name":"stone_bricks","properties":{}},{"x":16,"y":2,"z":18,"name":"cobblestone_wall","properties":{"east":"tall","waterlogged":"false","south":"none","north":"none","west":"tall","up":"false"}},{"x":17,"y":2,"z":18,"name":"cracked_stone_bricks","properties":{}},{"x":18,"y":2,"z":18,"name":"stone_bricks","properties":{}},{"x":22,"y":2,"z":18,"name":"stone","properties":{}},{"x":23,"y":2,"z":18,"name":"cobblestone_wall","properties":{"east":"none","waterlogged":"false","south":"none","north":"tall","west":"tall","up":"true"}},{"x":24,"y":2,"z":18,"name":"dark_oak_fence","properties":{"east":"false","waterlogged":"false","south":"true","north":"true","west":"false"}},{"x":27,"y":2,"z":18,"name":"spruce_fence","properties":{"east":"false","waterlogged":"false","south":"false","north":"true","west":"false"}},{"x":6,"y":2,"z":19,"name":"stripped_spruce_wood","properties":{"axis":"y"}},{"x":7,"y":2,"z":19,"name":"stone_bricks","properties":{}},{"x":12,"y":2,"z":19,"name":"barrel","properties":{"facing":"west","open":"false"},"nbt":{"x":12,"y":2,"Items":[],"z":19,"id":"minecraft:barrel"}},{"x":13,"y":2,"z":19,"name":"cobblestone","properties":{}},{"x":14,"y":2,"z":19,"name":"stripped_spruce_wood","properties":{"axis":"y"}},{"x":15,"y":2,"z":19,"name":"dark_oak_fence","properties":{"east":"false","waterlogged":"false","south":"false","north":"true","west":"true"}},{"x":23,"y":2,"z":19,"name":"dark_oak_fence","properties":{"east":"true","waterlogged":"false","south":"false","north":"false","west":"false"}},{"x":24,"y":2,"z":19,"name":"stripped_spruce_wood","properties":{"axis":"y"}},{"x":27,"y":2,"z":19,"name":"spruce_trapdoor","properties":{"half":"bottom","waterlogged":"false","powered":"false","facing":"south","open":"false"}},{"x":6,"y":2,"z":20,"name":"dark_oak_fence","properties":{"east":"true","waterlogged":"false","south":"false","north":"true","west":"false"}},{"x":7,"y":2,"z":20,"name":"stone_bricks","properties":{}},{"x":8,"y":2,"z":20,"name":"cobblestone_wall","properties":{"east":"none","waterlogged":"false","south":"none","north":"none","west":"tall","up":"true"}},{"x":12,"y":2,"z":20,"name":"barrel","properties":{"facing":"west","open":"false"},"nbt":{"x":12,"y":2,"Items":[],"z":20,"id":"minecraft:barrel"}},{"x":13,"y":2,"z":20,"name":"stone","properties":{}},{"x":14,"y":2,"z":20,"name":"dark_oak_fence","properties":{"east":"false","waterlogged":"false","south":"false","north":"true","west":"true"}},{"x":7,"y":2,"z":21,"name":"cobblestone_wall","properties":{"east":"none","waterlogged":"false","south":"tall","north":"tall","west":"none","up":"false"}},{"x":12,"y":2,"z":21,"name":"bookshelf","properties":{}},{"x":13,"y":2,"z":21,"name":"cobblestone_wall","properties":{"east":"none","waterlogged":"false","south":"tall","north":"tall","west":"tall","up":"true"}},{"x":16,"y":2,"z":21,"name":"dark_oak_fence","properties":{"east":"false","waterlogged":"false","south":"false","north":"false","west":"false"}},{"x":7,"y":2,"z":22,"name":"glass_pane","properties":{"east":"false","waterlogged":"false","south":"true","north":"true","west":"false"}},{"x":13,"y":2,"z":22,"name":"glass_pane","properties":{"east":"false","waterlogged":"false","south":"true","north":"true","west":"false"}},{"x":7,"y":2,"z":23,"name":"glass_pane","properties":{"east":"false","waterlogged":"false","south":"true","north":"true","west":"false"}},{"x":13,"y":2,"z":23,"name":"glass_pane","properties":{"east":"false","waterlogged":"false","south":"true","north":"true","west":"false"}},{"x":7,"y":2,"z":24,"name":"glass_pane","properties":{"east":"false","waterlogged":"false","south":"true","north":"true","west":"false"}},{"x":13,"y":2,"z":24,"name":"glass_pane","properties":{"east":"false","waterlogged":"false","south":"true","north":"true","west":"false"}},{"x":7,"y":2,"z":25,"name":"stone","properties":{}},{"x":13,"y":2,"z":25,"name":"cracked_stone_bricks","properties":{}},{"x":16,"y":2,"z":25,"name":"dark_oak_fence","properties":{"east":"false","waterlogged":"false","south":"false","north":"false","west":"false"}},{"x":6,"y":2,"z":26,"name":"dark_oak_fence","properties":{"east":"true","waterlogged":"false","south":"true","north":"false","west":"false"}},{"x":7,"y":2,"z":26,"name":"stone","properties":{}},{"x":8,"y":2,"z":26,"name":"stone_bricks","properties":{}},{"x":9,"y":2,"z":26,"name":"glass_pane","properties":{"east":"true","waterlogged":"false","south":"false","north":"false","west":"true"}},{"x":10,"y":2,"z":26,"name":"glass_pane","properties":{"east":"true","waterlogged":"false","south":"false","north":"false","west":"true"}},{"x":11,"y":2,"z":26,"name":"glass_pane","properties":{"east":"true","waterlogged":"false","south":"false","north":"false","west":"true"}},{"x":12,"y":2,"z":26,"name":"cobblestone","properties":{}},{"x":13,"y":2,"z":26,"name":"stone","properties":{}},{"x":14,"y":2,"z":26,"name":"dark_oak_fence","properties":{"east":"false","waterlogged":"false","south":"true","north":"false","west":"true"}},{"x":6,"y":2,"z":27,"name":"stripped_spruce_wood","properties":{"axis":"y"}},{"x":7,"y":2,"z":27,"name":"dark_oak_fence","properties":{"east":"false","waterlogged":"false","south":"false","north":"true","west":"true"}},{"x":8,"y":2,"z":27,"name":"spruce_trapdoor","properties":{"half":"top","waterlogged":"false","powered":"false","facing":"south","open":"true"}},{"x":12,"y":2,"z":27,"name":"spruce_trapdoor","properties":{"half":"top","waterlogged":"false","powered":"false","facing":"south","open":"true"}},{"x":13,"y":2,"z":27,"name":"dark_oak_fence","properties":{"east":"true","waterlogged":"false","south":"false","north":"true","west":"false"}},{"x":14,"y":2,"z":27,"name":"stripped_spruce_wood","properties":{"axis":"y"}},{"x":6,"y":3,"z":5,"name":"lantern","properties":{"waterlogged":"false","hanging":"true"}},{"x":14,"y":3,"z":5,"name":"lantern","properties":{"waterlogged":"false","hanging":"true"}},{"x":5,"y":3,"z":6,"name":"lantern","properties":{"waterlogged":"false","hanging":"true"}},{"x":6,"y":3,"z":6,"name":"stripped_spruce_wood","properties":{"axis":"y"}},{"x":7,"y":3,"z":6,"name":"dark_oak_fence","properties":{"east":"false","waterlogged":"false","south":"true","north":"false","west":"true"}},{"x":13,"y":3,"z":6,"name":"dark_oak_fence","properties":{"east":"true","waterlogged":"false","south":"true","north":"false","west":"false"}},{"x":14,"y":3,"z":6,"name":"stripped_spruce_wood","properties":{"axis":"y"}},{"x":15,"y":3,"z":6,"name":"lantern","properties":{"waterlogged":"false","hanging":"true"}},{"x":6,"y":3,"z":7,"name":"dark_oak_fence","properties":{"east":"true","waterlogged":"false","south":"false","north":"true","west":"false"}},{"x":7,"y":3,"z":7,"name":"stone","properties":{}},{"x":8,"y":3,"z":7,"name":"cobblestone","properties":{}},{"x":9,"y":3,"z":7,"name":"stone","properties":{}},{"x":10,"y":3,"z":7,"name":"cobblestone","properties":{}},{"x":11,"y":3,"z":7,"name":"cobblestone","properties":{}},{"x":12,"y":3,"z":7,"name":"stone_bricks","properties":{}},{"x":13,"y":3,"z":7,"name":"stone_bricks","properties":{}},{"x":14,"y":3,"z":7,"name":"dark_oak_fence","properties":{"east":"false","waterlogged":"false","south":"false","north":"true","west":"true"}},{"x":7,"y":3,"z":8,"name":"stone","properties":{}},{"x":8,"y":3,"z":8,"name":"spruce_fence","properties":{"east":"false","waterlogged":"false","south":"false","north":"true","west":"true"}},{"x":11,"y":3,"z":8,"name":"cobweb","properties":{}},{"x":12,"y":3,"z":8,"name":"spruce_fence","properties":{"east":"true","waterlogged":"false","south":"false","north":"true","west":"false"}},{"x":13,"y":3,"z":8,"name":"cobblestone","properties":{}},{"x":24,"y":3,"z":8,"name":"lantern","properties":{"waterlogged":"false","hanging":"true"}},{"x":5,"y":3,"z":9,"name":"lantern","properties":{"waterlogged":"false","hanging":"true"}},{"x":6,"y":3,"z":9,"name":"stripped_spruce_wood","properties":{"axis":"y"}},{"x":7,"y":3,"z":9,"name":"cobblestone","properties":{}},{"x":13,"y":3,"z":9,"name":"stone_bricks","properties":{}},{"x":14,"y":3,"z":9,"name":"stripped_spruce_wood","properties":{"axis":"y"}},{"x":15,"y":3,"z":9,"name":"dark_oak_fence","properties":{"east":"false","waterlogged":"false","south":"true","north":"false","west":"true"}},{"x":19,"y":3,"z":9,"name":"dark_oak_fence","properties":{"east":"false","waterlogged":"false","south":"true","north":"false","west":"false"}},{"x":23,"y":3,"z":9,"name":"dark_oak_fence","properties":{"east":"true","waterlogged":"false","south":"true","north":"false","west":"false"}},{"x":24,"y":3,"z":9,"name":"stripped_spruce_wood","properties":{"axis":"y"}},{"x":25,"y":3,"z":9,"name":"spruce_stairs","properties":{"half":"top","waterlogged":"false","shape":"straight","facing":"west"}},{"x":26,"y":3,"z":9,"name":"spruce_stairs","properties":{"half":"top","waterlogged":"false","shape":"straight","facing":"east"}},{"x":27,"y":3,"z":9,"name":"stripped_spruce_log","properties":{"axis":"y"}},{"x":28,"y":3,"z":9,"name":"spruce_trapdoor","properties":{"half":"top","waterlogged":"false","powered":"false","facing":"east","open":"true"}},{"x":6,"y":3,"z":10,"name":"dark_oak_fence","properties":{"east":"true","waterlogged":"false","south":"false","north":"true","west":"false"}},{"x":7,"y":3,"z":10,"name":"cracked_stone_bricks","properties":{}},{"x":13,"y":3,"z":10,"name":"stone_bricks","properties":{}},{"x":14,"y":3,"z":10,"name":"stone","properties":{}},{"x":15,"y":3,"z":10,"name":"stone_bricks","properties":{}},{"x":16,"y":3,"z":10,"name":"cracked_stone_bricks","properties":{}},{"x":17,"y":3,"z":10,"name":"cobblestone","properties":{}},{"x":18,"y":3,"z":10,"name":"cobblestone","properties":{}},{"x":19,"y":3,"z":10,"name":"cobblestone","properties":{}},{"x":20,"y":3,"z":10,"name":"cracked_stone_bricks","properties":{}},{"x":21,"y":3,"z":10,"name":"stone_bricks","properties":{}},{"x":22,"y":3,"z":10,"name":"cracked_stone_bricks","properties":{}},{"x":23,"y":3,"z":10,"name":"stone_bricks","properties":{}},{"x":27,"y":3,"z":10,"name":"spruce_stairs","properties":{"half":"top","waterlogged":"false","shape":"straight","facing":"north"}},{"x":7,"y":3,"z":11,"name":"stone_bricks","properties":{}},{"x":18,"y":3,"z":11,"name":"spruce_fence","properties":{"east":"false","waterlogged":"false","south":"false","north":"true","west":"false"}},{"x":21,"y":3,"z":11,"name":"cobweb","properties":{}},{"x":22,"y":3,"z":11,"name":"dark_oak_stairs","properties":{"half":"top","waterlogged":"false","shape":"straight","facing":"east"}},{"x":23,"y":3,"z":11,"name":"stone_bricks","properties":{}},{"x":27,"y":3,"z":11,"name":"spruce_trapdoor","properties":{"half":"top","waterlogged":"false","powered":"false","facing":"east","open":"false"}},{"x":7,"y":3,"z":12,"name":"cobblestone_wall","properties":{"east":"none","waterlogged":"false","south":"tall","north":"tall","west":"none","up":"false"}},{"x":22,"y":3,"z":12,"name":"dark_oak_stairs","properties":{"half":"top","waterlogged":"false","shape":"straight","facing":"east"}},{"x":23,"y":3,"z":12,"name":"stone","properties":{}},{"x":25,"y":3,"z":12,"name":"lantern","properties":{"waterlogged":"false","hanging":"true"}},{"x":7,"y":3,"z":13,"name":"cobblestone_wall","properties":{"east":"none","waterlogged":"false","south":"tall","north":"tall","west":"none","up":"false"}},{"x":9,"y":3,"z":13,"name":"cobweb","properties":{}},{"x":22,"y":3,"z":13,"name":"dark_oak_stairs","properties":{"half":"top","waterlogged":"false","shape":"straight","facing":"east"}},{"x":23,"y":3,"z":13,"name":"cobblestone_wall","properties":{"east":"none","waterlogged":"false","south":"tall","north":"tall","west":"tall","up":"true"}},{"x":27,"y":3,"z":13,"name":"spruce_trapdoor","properties":{"half":"top","waterlogged":"false","powered":"false","facing":"east","open":"false"}},{"x":7,"y":3,"z":14,"name":"stone_bricks","properties":{}},{"x":8,"y":3,"z":14,"name":"cobweb","properties":{}},{"x":22,"y":3,"z":14,"name":"dark_oak_stairs","properties":{"half":"top","waterlogged":"false","shape":"straight","facing":"east"}},{"x":23,"y":3,"z":14,"name":"cobblestone_wall","properties":{"east":"none","waterlogged":"false","south":"tall","north":"tall","west":"tall","up":"true"}},{"x":27,"y":3,"z":14,"name":"spruce_stairs","properties":{"half":"top","waterlogged":"false","shape":"straight","facing":"south"}},{"x":7,"y":3,"z":15,"name":"stone","properties":{}},{"x":13,"y":3,"z":15,"name":"spruce_trapdoor","properties":{"half":"top","waterlogged":"false","powered":"false","facing":"north","open":"true"}},{"x":14,"y":3,"z":15,"name":"spruce_trapdoor","properties":{"half":"bottom","waterlogged":"false","powered":"false","facing":"north","open":"true"}},{"x":22,"y":3,"z":15,"name":"dark_oak_stairs","properties":{"half":"top","waterlogged":"false","shape":"straight","facing":"east"}},{"x":23,"y":3,"z":15,"name":"cobblestone","properties":{}},{"x":24,"y":3,"z":15,"name":"stripped_spruce_log","properties":{"axis":"y"}},{"x":25,"y":3,"z":15,"name":"spruce_stairs","properties":{"half":"top","waterlogged":"false","shape":"straight","facing":"south"}},{"x":26,"y":3,"z":15,"name":"spruce_stairs","properties":{"half":"top","waterlogged":"false","shape":"straight","facing":"south"}},{"x":27,"y":3,"z":15,"name":"stripped_spruce_log","properties":{"axis":"y"}},{"x":28,"y":3,"z":15,"name":"spruce_trapdoor","properties":{"half":"top","waterlogged":"false","powered":"false","facing":"east","open":"true"}},{"x":7,"y":3,"z":16,"name":"cobblestone","properties":{}},{"x":8,"y":3,"z":16,"name":"barrel","properties":{"facing":"east","open":"false"},"nbt":{"x":8,"y":3,"Items":[],"z":16,"id":"minecraft:barrel"}},{"x":13,"y":3,"z":16,"name":"polished_deepslate_stairs","properties":{"half":"top","waterlogged":"false","shape":"straight","facing":"east"}},{"x":14,"y":3,"z":16,"name":"polished_deepslate_stairs","properties":{"half":"bottom","waterlogged":"false","shape":"straight","facing":"west"}},{"x":22,"y":3,"z":16,"name":"dark_oak_stairs","properties":{"half":"top","waterlogged":"false","shape":"straight","facing":"east"}},{"x":23,"y":3,"z":16,"name":"cobblestone","properties":{}},{"x":24,"y":3,"z":16,"name":"stripped_spruce_log","properties":{"axis":"y"}},{"x":25,"y":3,"z":16,"name":"spruce_stairs","properties":{"half":"bottom","waterlogged":"false","shape":"straight","facing":"north"}},{"x":26,"y":3,"z":16,"name":"spruce_stairs","properties":{"half":"bottom","waterlogged":"false","shape":"straight","facing":"north"}},{"x":27,"y":3,"z":16,"name":"stripped_spruce_log","properties":{"axis":"y"}},{"x":7,"y":3,"z":17,"name":"cracked_stone_bricks","properties":{}},{"x":8,"y":3,"z":17,"name":"dark_oak_planks","properties":{}},{"x":9,"y":3,"z":17,"name":"dark_oak_slab","properties":{"waterlogged":"false","type":"double"}},{"x":10,"y":3,"z":17,"name":"dark_oak_slab","properties":{"waterlogged":"false","type":"top"}},{"x":11,"y":3,"z":17,"name":"dark_oak_slab","properties":{"waterlogged":"false","type":"top"}},{"x":12,"y":3,"z":17,"name":"dark_oak_slab","properties":{"waterlogged":"false","type":"double"}},{"x":13,"y":3,"z":17,"name":"stripped_dark_oak_wood","properties":{"axis":"y"}},{"x":14,"y":3,"z":17,"name":"polished_deepslate_stairs","properties":{"half":"bottom","waterlogged":"false","shape":"straight","facing":"west"}},{"x":19,"y":3,"z":17,"name":"spruce_trapdoor","properties":{"half":"bottom","waterlogged":"false","powered":"false","facing":"north","open":"true"}},{"x":20,"y":3,"z":17,"name":"spruce_trapdoor","properties":{"half":"bottom","waterlogged":"false","powered":"false","facing":"north","open":"true"}},{"x":21,"y":3,"z":17,"name":"spruce_trapdoor","properties":{"half":"bottom","waterlogged":"false","powered":"false","facing":"north","open":"true"}},{"x":22,"y":3,"z":17,"name":"dark_oak_stairs","properties":{"half":"top","waterlogged":"false","shape":"straight","facing":"east"}},{"x":23,"y":3,"z":17,"name":"stone","properties":{}},{"x":24,"y":3,"z":17,"name":"dark_oak_fence","properties":{"east":"false","waterlogged":"false","south":"false","north":"true","west":"true"}},{"x":27,"y":3,"z":17,"name":"spruce_fence","properties":{"east":"false","waterlogged":"false","south":"false","north":"true","west":"false"}},{"x":6,"y":3,"z":18,"name":"dark_oak_fence","properties":{"east":"true","waterlogged":"false","south":"true","north":"false","west":"false"}},{"x":7,"y":3,"z":18,"name":"cracked_stone_bricks","properties":{}},{"x":8,"y":3,"z":18,"name":"cobweb","properties":{}},{"x":11,"y":3,"z":18,"name":"ladder","properties":{"waterlogged":"false","facing":"west"}},{"x":12,"y":3,"z":18,"name":"bookshelf","properties":{}},{"x":13,"y":3,"z":18,"name":"stone","properties":{}},{"x":14,"y":3,"z":18,"name":"stone_bricks","properties":{}},{"x":15,"y":3,"z":18,"name":"cracked_stone_bricks","properties":{}},{"x":16,"y":3,"z":18,"name":"cobblestone","properties":{}},{"x":17,"y":3,"z":18,"name":"stone","properties":{}},{"x":18,"y":3,"z":18,"name":"cobblestone_wall","properties":{"east":"tall","waterlogged":"false","south":"none","north":"none","west":"tall","up":"false"}},{"x":19,"y":3,"z":18,"name":"stone_brick_stairs","properties":{"half":"top","waterlogged":"false","shape":"straight","facing":"west"}},{"x":21,"y":3,"z":18,"name":"stone_brick_stairs","properties":{"half":"top","waterlogged":"false","shape":"straight","facing":"east"}},{"x":22,"y":3,"z":18,"name":"cobblestone_wall","properties":{"east":"tall","waterlogged":"false","south":"none","north":"none","west":"tall","up":"false"}},{"x":23,"y":3,"z":18,"name":"cobblestone","properties":{}},{"x":24,"y":3,"z":18,"name":"spruce_trapdoor","properties":{"half":"bottom","waterlogged":"false","powered":"false","facing":"east","open":"false"}},{"x":27,"y":3,"z":18,"name":"spruce_trapdoor","properties":{"half":"bottom","waterlogged":"false","powered":"false","facing":"south","open":"false"}},{"x":5,"y":3,"z":19,"name":"lantern","properties":{"waterlogged":"false","hanging":"true"}},{"x":6,"y":3,"z":19,"name":"stripped_spruce_wood","properties":{"axis":"y"}},{"x":7,"y":3,"z":19,"name":"cracked_stone_bricks","properties":{}},{"x":12,"y":3,"z":19,"name":"barrel","properties":{"facing":"west","open":"false"},"nbt":{"x":12,"y":3,"Items":[],"z":19,"id":"minecraft:barrel"}},{"x":13,"y":3,"z":19,"name":"cobblestone","properties":{}},{"x":14,"y":3,"z":19,"name":"stripped_spruce_wood","properties":{"axis":"y"}},{"x":15,"y":3,"z":19,"name":"dark_oak_fence","properties":{"east":"false","waterlogged":"false","south":"false","north":"true","west":"true"}},{"x":23,"y":3,"z":19,"name":"dark_oak_fence","properties":{"east":"true","waterlogged":"false","south":"false","north":"true","west":"false"}},{"x":24,"y":3,"z":19,"name":"stripped_spruce_wood","properties":{"axis":"y"}},{"x":6,"y":3,"z":20,"name":"dark_oak_fence","properties":{"east":"true","waterlogged":"false","south":"false","north":"true","west":"false"}},{"x":7,"y":3,"z":20,"name":"cobblestone","properties":{}},{"x":8,"y":3,"z":20,"name":"cobblestone_wall","properties":{"east":"none","waterlogged":"false","south":"none","north":"none","west":"tall","up":"true"}},{"x":12,"y":3,"z":20,"name":"barrel","properties":{"facing":"west","open":"false"},"nbt":{"x":12,"y":3,"Items":[],"z":20,"id":"minecraft:barrel"}},{"x":13,"y":3,"z":20,"name":"stone_bricks","properties":{}},{"x":14,"y":3,"z":20,"name":"dark_oak_fence","properties":{"east":"false","waterlogged":"false","south":"false","north":"true","west":"true"}},{"x":24,"y":3,"z":20,"name":"lantern","properties":{"waterlogged":"false","hanging":"true"}},{"x":7,"y":3,"z":21,"name":"cobblestone","properties":{}},{"x":11,"y":3,"z":21,"name":"ladder","properties":{"waterlogged":"false","facing":"west"}},{"x":12,"y":3,"z":21,"name":"bookshelf","properties":{}},{"x":13,"y":3,"z":21,"name":"cobblestone","properties":{}},{"x":14,"y":3,"z":21,"name":"spruce_trapdoor","properties":{"half":"top","waterlogged":"false","powered":"false","facing":"east","open":"false"}},{"x":15,"y":3,"z":21,"name":"spruce_trapdoor","properties":{"half":"top","waterlogged":"false","powered":"false","facing":"east","open":"false"}},{"x":16,"y":3,"z":21,"name":"cobblestone_wall","properties":{"east":"none","waterlogged":"false","south":"none","north":"none","west":"none","up":"true"}},{"x":7,"y":3,"z":22,"name":"stone_bricks","properties":{}},{"x":13,"y":3,"z":22,"name":"stone_brick_stairs","properties":{"half":"top","waterlogged":"false","shape":"straight","facing":"west"}},{"x":14,"y":3,"z":22,"name":"spruce_trapdoor","properties":{"half":"top","waterlogged":"false","powered":"false","facing":"east","open":"false"}},{"x":15,"y":3,"z":22,"name":"spruce_trapdoor","properties":{"half":"top","waterlogged":"false","powered":"false","facing":"east","open":"false"}},{"x":16,"y":3,"z":22,"name":"spruce_trapdoor","properties":{"half":"top","waterlogged":"false","powered":"false","facing":"east","open":"false"}},{"x":7,"y":3,"z":23,"name":"cobblestone","properties":{}},{"x":12,"y":3,"z":23,"name":"cobweb","properties":{}},{"x":13,"y":3,"z":23,"name":"stone_brick_stairs","properties":{"half":"top","waterlogged":"false","shape":"straight","facing":"west"}},{"x":14,"y":3,"z":23,"name":"spruce_trapdoor","properties":{"half":"top","waterlogged":"false","powered":"false","facing":"east","open":"false"}},{"x":15,"y":3,"z":23,"name":"spruce_trapdoor","properties":{"half":"top","waterlogged":"false","powered":"false","facing":"east","open":"false"}},{"x":16,"y":3,"z":23,"name":"spruce_trapdoor","properties":{"half":"top","waterlogged":"false","powered":"false","facing":"east","open":"false"}},{"x":7,"y":3,"z":24,"name":"cobblestone_wall","properties":{"east":"none","waterlogged":"false","south":"tall","north":"tall","west":"none","up":"false"}},{"x":13,"y":3,"z":24,"name":"stone_brick_stairs","properties":{"half":"top","waterlogged":"false","shape":"straight","facing":"west"}},{"x":14,"y":3,"z":24,"name":"spruce_trapdoor","properties":{"half":"top","waterlogged":"false","powered":"false","facing":"east","open":"false"}},{"x":15,"y":3,"z":24,"name":"spruce_trapdoor","properties":{"half":"top","waterlogged":"false","powered":"false","facing":"east","open":"false"}},{"x":16,"y":3,"z":24,"name":"spruce_trapdoor","properties":{"half":"top","waterlogged":"false","powered":"false","facing":"east","open":"false"}},{"x":7,"y":3,"z":25,"name":"stone_bricks","properties":{}},{"x":8,"y":3,"z":25,"name":"cobweb","properties":{}},{"x":12,"y":3,"z":25,"name":"cobweb","properties":{}},{"x":13,"y":3,"z":25,"name":"stone","properties":{}},{"x":14,"y":3,"z":25,"name":"spruce_trapdoor","properties":{"half":"top","waterlogged":"false","powered":"false","facing":"east","open":"false"}},{"x":15,"y":3,"z":25,"name":"spruce_trapdoor","properties":{"half":"top","waterlogged":"false","powered":"false","facing":"east","open":"false"}},{"x":16,"y":3,"z":25,"name":"cobblestone_wall","properties":{"east":"none","waterlogged":"false","south":"none","north":"none","west":"none","up":"true"}},{"x":6,"y":3,"z":26,"name":"dark_oak_fence","properties":{"east":"true","waterlogged":"false","south":"true","north":"false","west":"false"}},{"x":7,"y":3,"z":26,"name":"stone_bricks","properties":{}},{"x":8,"y":3,"z":26,"name":"cracked_stone_bricks","properties":{}},{"x":9,"y":3,"z":26,"name":"stone_brick_stairs","properties":{"half":"top","waterlogged":"false","shape":"straight","facing":"north"}},{"x":10,"y":3,"z":26,"name":"stone_brick_stairs","properties":{"half":"top","waterlogged":"false","shape":"straight","facing":"north"}},{"x":11,"y":3,"z":26,"name":"stone_brick_stairs","properties":{"half":"top","waterlogged":"false","shape":"straight","facing":"north"}},{"x":12,"y":3,"z":26,"name":"stone","properties":{}},{"x":13,"y":3,"z":26,"name":"cobblestone","properties":{}},{"x":14,"y":3,"z":26,"name":"dark_oak_fence","properties":{"east":"false","waterlogged":"false","south":"true","north":"false","west":"true"}},{"x":5,"y":3,"z":27,"name":"lantern","properties":{"waterlogged":"false","hanging":"true"}},{"x":6,"y":3,"z":27,"name":"stripped_spruce_wood","properties":{"axis":"y"}},{"x":7,"y":3,"z":27,"name":"dark_oak_fence","properties":{"east":"false","waterlogged":"false","south":"false","north":"true","west":"true"}},{"x":8,"y":3,"z":27,"name":"spruce_trapdoor","properties":{"half":"top","waterlogged":"false","powered":"false","facing":"south","open":"true"}},{"x":12,"y":3,"z":27,"name":"spruce_trapdoor","properties":{"half":"top","waterlogged":"false","powered":"false","facing":"south","open":"true"}},{"x":13,"y":3,"z":27,"name":"dark_oak_fence","properties":{"east":"true","waterlogged":"false","south":"false","north":"true","west":"false"}},{"x":14,"y":3,"z":27,"name":"stripped_spruce_wood","properties":{"axis":"y"}},{"x":15,"y":3,"z":27,"name":"lantern","properties":{"waterlogged":"false","hanging":"true"}},{"x":6,"y":4,"z":4,"name":"stone_button","properties":{"face":"wall","powered":"false","facing":"north"}},{"x":14,"y":4,"z":4,"name":"stone_button","properties":{"face":"wall","powered":"false","facing":"north"}},{"x":6,"y":4,"z":5,"name":"stripped_spruce_log","properties":{"axis":"z"}},{"x":14,"y":4,"z":5,"name":"stripped_spruce_log","properties":{"axis":"z"}},{"x":4,"y":4,"z":6,"name":"stone_button","properties":{"face":"wall","powered":"false","facing":"west"}},{"x":5,"y":4,"z":6,"name":"stripped_spruce_log","properties":{"axis":"x"}},{"x":6,"y":4,"z":6,"name":"stripped_spruce_wood","properties":{"axis":"y"}},{"x":7,"y":4,"z":6,"name":"stone_brick_stairs","properties":{"half":"top","waterlogged":"false","shape":"straight","facing":"south"}},{"x":8,"y":4,"z":6,"name":"stone_brick_stairs","properties":{"half":"top","waterlogged":"false","shape":"straight","facing":"south"}},{"x":9,"y":4,"z":6,"name":"stone_brick_stairs","properties":{"half":"top","waterlogged":"false","shape":"straight","facing":"south"}},{"x":10,"y":4,"z":6,"name":"stone_brick_stairs","properties":{"half":"top","waterlogged":"false","shape":"straight","facing":"south"}},{"x":11,"y":4,"z":6,"name":"stone_brick_stairs","properties":{"half":"top","waterlogged":"false","shape":"straight","facing":"south"}},{"x":12,"y":4,"z":6,"name":"stone_brick_stairs","properties":{"half":"top","waterlogged":"false","shape":"straight","facing":"south"}},{"x":13,"y":4,"z":6,"name":"stone_brick_stairs","properties":{"half":"top","waterlogged":"false","shape":"straight","facing":"south"}},{"x":14,"y":4,"z":6,"name":"stripped_spruce_wood","properties":{"axis":"y"}},{"x":15,"y":4,"z":6,"name":"stripped_spruce_log","properties":{"axis":"x"}},{"x":16,"y":4,"z":6,"name":"stone_button","properties":{"face":"wall","powered":"false","facing":"east"}},{"x":6,"y":4,"z":7,"name":"stone_brick_stairs","properties":{"half":"top","waterlogged":"false","shape":"straight","facing":"east"}},{"x":7,"y":4,"z":7,"name":"stone","properties":{}},{"x":8,"y":4,"z":7,"name":"cracked_stone_bricks","properties":{}},{"x":9,"y":4,"z":7,"name":"stone","properties":{}},{"x":10,"y":4,"z":7,"name":"cracked_stone_bricks","properties":{}},{"x":11,"y":4,"z":7,"name":"stone_bricks","properties":{}},{"x":12,"y":4,"z":7,"name":"stone","properties":{}},{"x":13,"y":4,"z":7,"name":"stone","properties":{}},{"x":14,"y":4,"z":7,"name":"stone_brick_stairs","properties":{"half":"top","waterlogged":"false","shape":"straight","facing":"west"}},{"x":24,"y":4,"z":7,"name":"stone_button","properties":{"face":"wall","powered":"false","facing":"north"}},{"x":6,"y":4,"z":8,"name":"stone_brick_stairs","properties":{"half":"top","waterlogged":"false","shape":"straight","facing":"east"}},{"x":7,"y":4,"z":8,"name":"stone","properties":{}},{"x":8,"y":4,"z":8,"name":"dark_oak_planks","properties":{}},{"x":9,"y":4,"z":8,"name":"dark_oak_planks","properties":{}},{"x":10,"y":4,"z":8,"name":"dark_oak_planks","properties":{}},{"x":11,"y":4,"z":8,"name":"dark_oak_planks","properties":{}},{"x":12,"y":4,"z":8,"name":"dark_oak_planks","properties":{}},{"x":13,"y":4,"z":8,"name":"cobblestone","properties":{}},{"x":14,"y":4,"z":8,"name":"stone_brick_stairs","properties":{"half":"top","waterlogged":"false","shape":"straight","facing":"west"}},{"x":24,"y":4,"z":8,"name":"stripped_spruce_log","properties":{"axis":"z"}},{"x":4,"y":4,"z":9,"name":"stone_button","properties":{"face":"wall","powered":"false","facing":"west"}},{"x":5,"y":4,"z":9,"name":"stripped_spruce_log","properties":{"axis":"x"}},{"x":6,"y":4,"z":9,"name":"stripped_spruce_wood","properties":{"axis":"y"}},{"x":7,"y":4,"z":9,"name":"cobblestone","properties":{}},{"x":8,"y":4,"z":9,"name":"dark_oak_planks","properties":{}},{"x":9,"y":4,"z":9,"name":"dark_oak_planks","properties":{}},{"x":10,"y":4,"z":9,"name":"dark_oak_planks","properties":{}},{"x":11,"y":4,"z":9,"name":"dark_oak_planks","properties":{}},{"x":12,"y":4,"z":9,"name":"dark_oak_planks","properties":{}},{"x":13,"y":4,"z":9,"name":"stone","properties":{}},{"x":14,"y":4,"z":9,"name":"stripped_spruce_wood","properties":{"axis":"y"}},{"x":15,"y":4,"z":9,"name":"stone_brick_stairs","properties":{"half":"top","waterlogged":"false","shape":"straight","facing":"south"}},{"x":16,"y":4,"z":9,"name":"stone_brick_stairs","properties":{"half":"top","waterlogged":"false","shape":"straight","facing":"south"}},{"x":17,"y":4,"z":9,"name":"stone_brick_stairs","properties":{"half":"top","waterlogged":"false","shape":"straight","facing":"south"}},{"x":18,"y":4,"z":9,"name":"stone_brick_stairs","properties":{"half":"top","waterlogged":"false","shape":"straight","facing":"south"}},{"x":19,"y":4,"z":9,"name":"stone_brick_stairs","properties":{"half":"top","waterlogged":"false","shape":"straight","facing":"south"}},{"x":20,"y":4,"z":9,"name":"stone_brick_stairs","properties":{"half":"top","waterlogged":"false","shape":"straight","facing":"south"}},{"x":21,"y":4,"z":9,"name":"stone_brick_stairs","properties":{"half":"top","waterlogged":"false","shape":"straight","facing":"south"}},{"x":22,"y":4,"z":9,"name":"stone_brick_stairs","properties":{"half":"top","waterlogged":"false","shape":"straight","facing":"south"}},{"x":23,"y":4,"z":9,"name":"stone_brick_stairs","properties":{"half":"top","waterlogged":"false","shape":"straight","facing":"south"}},{"x":24,"y":4,"z":9,"name":"stripped_spruce_wood","properties":{"axis":"y"}},{"x":25,"y":4,"z":9,"name":"stripped_spruce_log","properties":{"axis":"x"}},{"x":26,"y":4,"z":9,"name":"stripped_spruce_log","properties":{"axis":"x"}},{"x":27,"y":4,"z":9,"name":"stripped_spruce_log","properties":{"axis":"y"}},{"x":6,"y":4,"z":10,"name":"stone_brick_stairs","properties":{"half":"top","waterlogged":"false","shape":"straight","facing":"east"}},{"x":7,"y":4,"z":10,"name":"cracked_stone_bricks","properties":{}},{"x":8,"y":4,"z":10,"name":"dark_oak_planks","properties":{}},{"x":9,"y":4,"z":10,"name":"dark_oak_planks","properties":{}},{"x":10,"y":4,"z":10,"name":"dark_oak_planks","properties":{}},{"x":11,"y":4,"z":10,"name":"dark_oak_planks","properties":{}},{"x":12,"y":4,"z":10,"name":"dark_oak_planks","properties":{}},{"x":13,"y":4,"z":10,"name":"stone","properties":{}},{"x":14,"y":4,"z":10,"name":"cracked_stone_bricks","properties":{}},{"x":15,"y":4,"z":10,"name":"cracked_stone_bricks","properties":{}},{"x":16,"y":4,"z":10,"name":"cracked_stone_bricks","properties":{}},{"x":17,"y":4,"z":10,"name":"stone","properties":{}},{"x":18,"y":4,"z":10,"name":"stone","properties":{}},{"x":19,"y":4,"z":10,"name":"stone_bricks","properties":{}},{"x":20,"y":4,"z":10,"name":"stone_bricks","properties":{}},{"x":21,"y":4,"z":10,"name":"cobblestone","properties":{}},{"x":22,"y":4,"z":10,"name":"cracked_stone_bricks","properties":{}},{"x":23,"y":4,"z":10,"name":"cracked_stone_bricks","properties":{}},{"x":24,"y":4,"z":10,"name":"spruce_slab","properties":{"waterlogged":"false","type":"top"}},{"x":25,"y":4,"z":10,"name":"spruce_slab","properties":{"waterlogged":"false","type":"top"}},{"x":26,"y":4,"z":10,"name":"spruce_slab","properties":{"waterlogged":"false","type":"top"}},{"x":27,"y":4,"z":10,"name":"stripped_spruce_log","properties":{"axis":"z"}},{"x":6,"y":4,"z":11,"name":"stone_brick_stairs","properties":{"half":"top","waterlogged":"false","shape":"straight","facing":"east"}},{"x":7,"y":4,"z":11,"name":"cobblestone","properties":{}},{"x":8,"y":4,"z":11,"name":"dark_oak_planks","properties":{}},{"x":9,"y":4,"z":11,"name":"dark_oak_planks","properties":{}},{"x":10,"y":4,"z":11,"name":"dark_oak_planks","properties":{}},{"x":11,"y":4,"z":11,"name":"dark_oak_planks","properties":{}},{"x":12,"y":4,"z":11,"name":"dark_oak_planks","properties":{}},{"x":13,"y":4,"z":11,"name":"dark_oak_planks","properties":{}},{"x":14,"y":4,"z":11,"name":"dark_oak_planks","properties":{}},{"x":15,"y":4,"z":11,"name":"dark_oak_planks","properties":{}},{"x":16,"y":4,"z":11,"name":"dark_oak_planks","properties":{}},{"x":17,"y":4,"z":11,"name":"dark_oak_planks","properties":{}},{"x":18,"y":4,"z":11,"name":"dark_oak_planks","properties":{}},{"x":19,"y":4,"z":11,"name":"dark_oak_planks","properties":{}},{"x":20,"y":4,"z":11,"name":"dark_oak_planks","properties":{}},{"x":21,"y":4,"z":11,"name":"dark_oak_planks","properties":{}},{"x":22,"y":4,"z":11,"name":"dark_oak_planks","properties":{}},{"x":23,"y":4,"z":11,"name":"stripped_dark_oak_wood","properties":{"axis":"z"}},{"x":24,"y":4,"z":11,"name":"spruce_slab","properties":{"waterlogged":"false","type":"top"}},{"x":25,"y":4,"z":11,"name":"spruce_slab","properties":{"waterlogged":"false","type":"top"}},{"x":26,"y":4,"z":11,"name":"spruce_slab","properties":{"waterlogged":"false","type":"top"}},{"x":27,"y":4,"z":11,"name":"stripped_spruce_log","properties":{"axis":"z"}},{"x":6,"y":4,"z":12,"name":"stone_brick_stairs","properties":{"half":"top","waterlogged":"false","shape":"straight","facing":"east"}},{"x":7,"y":4,"z":12,"name":"cobblestone","properties":{}},{"x":8,"y":4,"z":12,"name":"dark_oak_planks","properties":{}},{"x":9,"y":4,"z":12,"name":"dark_oak_planks","properties":{}},{"x":10,"y":4,"z":12,"name":"dark_oak_planks","properties":{}},{"x":11,"y":4,"z":12,"name":"dark_oak_planks","properties":{}},{"x":12,"y":4,"z":12,"name":"dark_oak_planks","properties":{}},{"x":13,"y":4,"z":12,"name":"dark_oak_planks","properties":{}},{"x":14,"y":4,"z":12,"name":"dark_oak_planks","properties":{}},{"x":15,"y":4,"z":12,"name":"dark_oak_planks","properties":{}},{"x":16,"y":4,"z":12,"name":"dark_oak_planks","properties":{}},{"x":17,"y":4,"z":12,"name":"dark_oak_planks","properties":{}},{"x":18,"y":4,"z":12,"name":"dark_oak_planks","properties":{}},{"x":19,"y":4,"z":12,"name":"dark_oak_planks","properties":{}},{"x":20,"y":4,"z":12,"name":"dark_oak_planks","properties":{}},{"x":21,"y":4,"z":12,"name":"dark_oak_planks","properties":{}},{"x":22,"y":4,"z":12,"name":"dark_oak_planks","properties":{}},{"x":23,"y":4,"z":12,"name":"stripped_dark_oak_wood","properties":{"axis":"z"}},{"x":24,"y":4,"z":12,"name":"spruce_slab","properties":{"waterlogged":"false","type":"top"}},{"x":25,"y":4,"z":12,"name":"spruce_slab","properties":{"waterlogged":"false","type":"double"}},{"x":26,"y":4,"z":12,"name":"spruce_slab","properties":{"waterlogged":"false","type":"double"}},{"x":27,"y":4,"z":12,"name":"stripped_spruce_log","properties":{"axis":"z"}},{"x":6,"y":4,"z":13,"name":"stone_brick_stairs","properties":{"half":"top","waterlogged":"false","shape":"straight","facing":"east"}},{"x":7,"y":4,"z":13,"name":"cracked_stone_bricks","properties":{}},{"x":8,"y":4,"z":13,"name":"dark_oak_planks","properties":{}},{"x":9,"y":4,"z":13,"name":"dark_oak_planks","properties":{}},{"x":10,"y":4,"z":13,"name":"dark_oak_planks","properties":{}},{"x":11,"y":4,"z":13,"name":"dark_oak_planks","properties":{}},{"x":12,"y":4,"z":13,"name":"dark_oak_planks","properties":{}},{"x":13,"y":4,"z":13,"name":"dark_oak_planks","properties":{}},{"x":14,"y":4,"z":13,"name":"dark_oak_planks","properties":{}},{"x":15,"y":4,"z":13,"name":"dark_oak_planks","properties":{}},{"x":16,"y":4,"z":13,"name":"dark_oak_planks","properties":{}},{"x":17,"y":4,"z":13,"name":"dark_oak_planks","properties":{}},{"x":18,"y":4,"z":13,"name":"dark_oak_planks","properties":{}},{"x":19,"y":4,"z":13,"name":"dark_oak_planks","properties":{}},{"x":20,"y":4,"z":13,"name":"dark_oak_planks","properties":{}},{"x":21,"y":4,"z":13,"name":"dark_oak_planks","properties":{}},{"x":22,"y":4,"z":13,"name":"dark_oak_planks","properties":{}},{"x":23,"y":4,"z":13,"name":"stripped_dark_oak_wood","properties":{"axis":"z"}},{"x":24,"y":4,"z":13,"name":"spruce_slab","properties":{"waterlogged":"false","type":"top"}},{"x":25,"y":4,"z":13,"name":"spruce_slab","properties":{"waterlogged":"false","type":"top"}},{"x":26,"y":4,"z":13,"name":"spruce_slab","properties":{"waterlogged":"false","type":"top"}},{"x":27,"y":4,"z":13,"name":"stripped_spruce_log","properties":{"axis":"z"}},{"x":6,"y":4,"z":14,"name":"stone_brick_stairs","properties":{"half":"top","waterlogged":"false","shape":"straight","facing":"east"}},{"x":7,"y":4,"z":14,"name":"stone_bricks","properties":{}},{"x":8,"y":4,"z":14,"name":"dark_oak_planks","properties":{}},{"x":9,"y":4,"z":14,"name":"dark_oak_planks","properties":{}},{"x":10,"y":4,"z":14,"name":"dark_oak_planks","properties":{}},{"x":11,"y":4,"z":14,"name":"dark_oak_planks","properties":{}},{"x":12,"y":4,"z":14,"name":"dark_oak_planks","properties":{}},{"x":13,"y":4,"z":14,"name":"dark_oak_planks","properties":{}},{"x":14,"y":4,"z":14,"name":"dark_oak_planks","properties":{}},{"x":15,"y":4,"z":14,"name":"dark_oak_planks","properties":{}},{"x":16,"y":4,"z":14,"name":"dark_oak_planks","properties":{}},{"x":17,"y":4,"z":14,"name":"dark_oak_planks","properties":{}},{"x":18,"y":4,"z":14,"name":"dark_oak_planks","properties":{}},{"x":19,"y":4,"z":14,"name":"dark_oak_planks","properties":{}},{"x":20,"y":4,"z":14,"name":"dark_oak_planks","properties":{}},{"x":21,"y":4,"z":14,"name":"dark_oak_planks","properties":{}},{"x":22,"y":4,"z":14,"name":"dark_oak_planks","properties":{}},{"x":23,"y":4,"z":14,"name":"cobblestone","properties":{}},{"x":24,"y":4,"z":14,"name":"spruce_slab","properties":{"waterlogged":"false","type":"top"}},{"x":25,"y":4,"z":14,"name":"spruce_stairs","properties":{"half":"top","waterlogged":"false","shape":"straight","facing":"south"}},{"x":26,"y":4,"z":14,"name":"spruce_stairs","properties":{"half":"top","waterlogged":"false","shape":"straight","facing":"south"}},{"x":27,"y":4,"z":14,"name":"stripped_spruce_log","properties":{"axis":"z"}},{"x":6,"y":4,"z":15,"name":"stone_brick_stairs","properties":{"half":"top","waterlogged":"false","shape":"straight","facing":"east"}},{"x":7,"y":4,"z":15,"name":"stone_bricks","properties":{}},{"x":8,"y":4,"z":15,"name":"dark_oak_planks","properties":{}},{"x":9,"y":4,"z":15,"name":"dark_oak_planks","properties":{}},{"x":10,"y":4,"z":15,"name":"dark_oak_planks","properties":{}},{"x":11,"y":4,"z":15,"name":"dark_oak_planks","properties":{}},{"x":12,"y":4,"z":15,"name":"dark_oak_planks","properties":{}},{"x":13,"y":4,"z":15,"name":"dark_oak_planks","properties":{}},{"x":14,"y":4,"z":15,"name":"dark_oak_planks","properties":{}},{"x":15,"y":4,"z":15,"name":"dark_oak_planks","properties":{}},{"x":16,"y":4,"z":15,"name":"dark_oak_planks","properties":{}},{"x":17,"y":4,"z":15,"name":"dark_oak_planks","properties":{}},{"x":18,"y":4,"z":15,"name":"dark_oak_planks","properties":{}},{"x":19,"y":4,"z":15,"name":"dark_oak_planks","properties":{}},{"x":20,"y":4,"z":15,"name":"dark_oak_planks","properties":{}},{"x":21,"y":4,"z":15,"name":"dark_oak_planks","properties":{}},{"x":22,"y":4,"z":15,"name":"dark_oak_planks","properties":{}},{"x":23,"y":4,"z":15,"name":"stone_bricks","properties":{}},{"x":24,"y":4,"z":15,"name":"stripped_spruce_log","properties":{"axis":"y"}},{"x":25,"y":4,"z":15,"name":"spruce_stairs","properties":{"half":"bottom","waterlogged":"false","shape":"straight","facing":"north"}},{"x":26,"y":4,"z":15,"name":"spruce_stairs","properties":{"half":"bottom","waterlogged":"false","shape":"straight","facing":"north"}},{"x":27,"y":4,"z":15,"name":"stripped_spruce_log","properties":{"axis":"y"}},{"x":6,"y":4,"z":16,"name":"stone_brick_stairs","properties":{"half":"top","waterlogged":"false","shape":"straight","facing":"east"}},{"x":7,"y":4,"z":16,"name":"stone_bricks","properties":{}},{"x":8,"y":4,"z":16,"name":"dark_oak_planks","properties":{}},{"x":9,"y":4,"z":16,"name":"dark_oak_planks","properties":{}},{"x":10,"y":4,"z":16,"name":"dark_oak_planks","properties":{}},{"x":11,"y":4,"z":16,"name":"dark_oak_planks","properties":{}},{"x":12,"y":4,"z":16,"name":"dark_oak_planks","properties":{}},{"x":13,"y":4,"z":16,"name":"polished_deepslate_stairs","properties":{"half":"bottom","waterlogged":"false","shape":"straight","facing":"west"}},{"x":17,"y":4,"z":16,"name":"dark_oak_stairs","properties":{"half":"top","waterlogged":"false","shape":"straight","facing":"east"}},{"x":18,"y":4,"z":16,"name":"dark_oak_planks","properties":{}},{"x":19,"y":4,"z":16,"name":"dark_oak_planks","properties":{}},{"x":20,"y":4,"z":16,"name":"dark_oak_planks","properties":{}},{"x":21,"y":4,"z":16,"name":"dark_oak_planks","properties":{}},{"x":22,"y":4,"z":16,"name":"dark_oak_planks","properties":{}},{"x":23,"y":4,"z":16,"name":"cobblestone","properties":{}},{"x":24,"y":4,"z":16,"name":"stone_brick_stairs","properties":{"half":"top","waterlogged":"false","shape":"straight","facing":"west"}},{"x":27,"y":4,"z":16,"name":"spruce_fence","properties":{"east":"false","waterlogged":"false","south":"false","north":"true","west":"false"}},